Workbook

Sheet 총합
B2: 1. Bottle market (Sales volume) | P2: [unit : c/s]
C3: SKU | D3: Y2025 | E3: Jan'26 | F3: Feb'26 | G3: Mar'26 | H3: Apr'26 | I3: May'26 | J3: Jun'26 | K3: Jul'26 | L3: Aug'26 | M3: Sep'26 | N3: Oct'26 | O3: Nov'26 | P3: Dec'26
B4: Western | C4: Heineken 33cl bottle | D4: =서울!D4+부산!D4+대전!D4+대구!D4+광주!D4 -> 47973 | E4: =서울!E4+부산!E4+대전!E4+대구!E4+광주!E4 -> 1911 | F4: =서울!F4+부산!F4+대전!F4+대구!F4+광주!F4 -> 2803 | G4: =서울!G4+부산!G4+대전!G4+대구!G4+광주!G4 -> 0 | H4: =서울!H4+부산!H4+대전!H4+대구!H4+광주!H4 -> 0 | I4: =서울!I4+부산!I4+대전!I4+대구!I4+광주!I4 -> 0 | J4: =서울!J4+부산!J4+대전!J4+대구!J4+광주!J4 -> 0 | K4: =서울!K4+부산!K4+대전!K4+대구!K4+광주!K4 -> 0 | ... P4: =서울!P4+부산!P4+대전!P4+대구!P4+광주!P4 -> 0 | R4: =D4/152878 -> 0.31379924
C5: Stellar 33cl bottle | D5: =서울!D5+부산!D5+대전!D5+대구!D5+광주!D5 -> 29646 | E5: =서울!E5+부산!E5+대전!E5+대구!E5+광주!E5 -> 1926 | F5: =서울!F5+부산!F5+대전!F5+대구!F5+광주!F5 -> 2054 | G5: =서울!G5+부산!G5+대전!G5+대구!G5+광주!G5 -> 0 | H5: =서울!H5+부산!H5+대전!H5+대구!H5+광주!H5 -> 0 | I5: =서울!I5+부산!I5+대전!I5+대구!I5+광주!I5 -> 0 | J5: =서울!J5+부산!J5+대전!J5+대구!J5+광주!J5 -> 0 | K5: =서울!K5+부산!K5+대전!K5+대구!K5+광주!K5 -> 0 | ... P5: =서울!P5+부산!P5+대전!P5+대구!P5+광주!P5 -> 0
C6: Bud 33cl bottle | D6: =서울!D6+부산!D6+대전!D6+대구!D6+광주!D6 -> 107897 | E6: =서울!E6+부산!E6+대전!E6+대구!E6+광주!E6 -> 6326 | F6: =서울!F6+부산!F6+대전!F6+대구!F6+광주!F6 -> 6806 | G6: =서울!G6+부산!G6+대전!G6+대구!G6+광주!G6 -> 0 | H6: =서울!H6+부산!H6+대전!H6+대구!H6+광주!H6 -> 0 | I6: =서울!I6+부산!I6+대전!I6+대구!I6+광주!I6 -> 0 | J6: =서울!J6+부산!J6+대전!J6+대구!J6+광주!J6 -> 0 | K6: =서울!K6+부산!K6+대전!K6+대구!K6+광주!K6 -> 0 | ... P6: =서울!P6+부산!P6+대전!P6+대구!P6+광주!P6 -> 0
C7: Corona 33cl bottle | D7: =서울!D7+부산!D7+대전!D7+대구!D7+광주!D7 -> 59502 | E7: =서울!E7+부산!E7+대전!E7+대구!E7+광주!E7 -> 4096 | F7: =서울!F7+부산!F7+대전!F7+대구!F7+광주!F7 -> 4389 | G7: =서울!G7+부산!G7+대전!G7+대구!G7+광주!G7 -> 0 | H7: =서울!H7+부산!H7+대전!H7+대구!H7+광주!H7 -> 0 | I7: =서울!I7+부산!I7+대전!I7+대구!I7+광주!I7 -> 0 | J7: =서울!J7+부산!J7+대전!J7+대구!J7+광주!J7 -> 0 | K7: =서울!K7+부산!K7+대전!K7+대구!K7+광주!K7 -> 0 | ... P7: =서울!P7+부산!P7+대전!P7+대구!P7+광주!P7 -> 0
B8: Total | D8: =서울!D8+부산!D8+대전!D8+대구!D8+광주!D8 -> 245018 | E8: =서울!E8+부산!E8+대전!E8+대구!E8+광주!E8 -> 14259 | F8: =서울!F8+부산!F8+대전!F8+대구!F8+광주!F8 -> 16052 | G8: =서울!G8+부산!G8+대전!G8+대구!G8+광주!G8 -> 0 | H8: =서울!H8+부산!H8+대전!H8+대구!H8+광주!H8 -> 0 | I8: =서울!I8+부산!I8+대전!I8+대구!I8+광주!I8 -> 0 | J8: =서울!J8+부산!J8+대전!J8+대구!J8+광주!J8 -> 0 | K8: =서울!K8+부산!K8+대전!K8+대구!K8+광주!K8 -> 0 | ... P8: =서울!P8+부산!P8+대전!P8+대구!P8+광주!P8 -> 0
B9: Chinese | C9: Sulwha 50cl bottle | D9: =서울!D9+부산!D9+대전!D9+대구!D9+광주!D9 -> 9199 | E9: =서울!E9+부산!E9+대전!E9+대구!E9+광주!E9 -> 750.2 | F9: =서울!F9+부산!F9+대전!F9+대구!F9+광주!F9 -> 873 | G9: =서울!G9+부산!G9+대전!G9+대구!G9+광주!G9 -> 0 | H9: =서울!H9+부산!H9+대전!H9+대구!H9+광주!H9 -> 0 | I9: =서울!I9+부산!I9+대전!I9+대구!I9+광주!I9 -> 0 | J9: =서울!J9+부산!J9+대전!J9+대구!J9+광주!J9 -> 0 | K9: =서울!K9+부산!K9+대전!K9+대구!K9+광주!K9 -> 0 | ... P9: =서울!P9+부산!P9+대전!P9+대구!P9+광주!P9 -> 0 | R9: =D9/19116 -> 0.48121992
C10: Harbin 50cl & 64cl bottle | D10: =서울!D10+부산!D10+대전!D10+대구!D10+광주!D10 -> 51637 | E10: =서울!E10+부산!E10+대전!E10+대구!E10+광주!E10 -> 3785 | F10: =서울!F10+부산!F10+대전!F10+대구!F10+광주!F10 -> 4594 | G10: =서울!G10+부산!G10+대전!G10+대구!G10+광주!G10 -> 0 | H10: =서울!H10+부산!H10+대전!H10+대구!H10+광주!H10 -> 0 | I10: =서울!I10+부산!I10+대전!I10+대구!I10+광주!I10 -> 0 | J10: =서울!J10+부산!J10+대전!J10+대구!J10+광주!J10 -> 0 | K10: =서울!K10+부산!K10+대전!K10+대구!K10+광주!K10 -> 0 | ... P10: =서울!P10+부산!P10+대전!P10+대구!P10+광주!P10 -> 0
C11: Tsingtao 64cl bottle | D11: =서울!D11+부산!D11+대전!D11+대구!D11+광주!D11 -> 183825 | E11: =서울!E11+부산!E11+대전!E11+대구!E11+광주!E11 -> 15511 | F11: =서울!F11+부산!F11+대전!F11+대구!F11+광주!F11 -> 16264 | G11: =서울!G11+부산!G11+대전!G11+대구!G11+광주!G11 -> 0 | H11: =서울!H11+부산!H11+대전!H11+대구!H11+광주!H11 -> 0 | I11: =서울!I11+부산!I11+대전!I11+대구!I11+광주!I11 -> 0 | J11: =서울!J11+부산!J11+대전!J11+대구!J11+광주!J11 -> 0 | K11: =서울!K11+부산!K11+대전!K11+대구!K11+광주!K11 -> 0 | ... P11: =서울!P11+부산!P11+대전!P11+대구!P11+광주!P11 -> 0
B12: Total | D12: =서울!D12+부산!D12+대전!D12+대구!D12+광주!D12 -> 244661 | E12: =서울!E12+부산!E12+대전!E12+대구!E12+광주!E12 -> 20046.2 | F12: =서울!F12+부산!F12+대전!F12+대구!F12+광주!F12 -> 21731 | G12: =서울!G12+부산!G12+대전!G12+대구!G12+광주!G12 -> 0 | H12: =서울!H12+부산!H12+대전!H12+대구!H12+광주!H12 -> 0 | I12: =서울!I12+부산!I12+대전!I12+대구!I12+광주!I12 -> 0 | J12: =서울!J12+부산!J12+대전!J12+대구!J12+광주!J12 -> 0 | K12: =서울!K12+부산!K12+대전!K12+대구!K12+광주!K12 -> 0 | ... P12: =서울!P12+부산!P12+대전!P12+대구!P12+광주!P12 -> 0
B14: 1-1. Bottle market (Market share) | P14: [단위:케이스]
C15: SKU | D15: Y2025 | E15: Jan'26 | F15: Feb'26 | G15: Mar'26 | H15: Apr'26 | I15: May'26 | J15: Jun'26 | K15: Jul'26 | L15: Aug'26 | M15: Sep'26 | N15: Oct'26 | O15: Nov'26 | P15: Dec'26
B16: Western | C16: Heineken 33cl bottle | D16: =D4/$D$8 -> 0.19579378 | E16: =E4/$E$8 -> 0.13402062 | F16: =F4/$F$8 -> 0.17461999
C17: Stellar 33cl bottle | D17: =D5/$D$8 -> 0.12099519 | E17: =E5/$E$8 -> 0.13507259 | F17: =F5/$F$8 -> 0.12795913
C18: Bud 33cl bottle | D18: =D6/$D$8 -> 0.44036357 | E18: =E6/$E$8 -> 0.44364962 | F18: =F6/$F$8 -> 0.42399701
C19: Corona 33cl bottle | D19: =D7/$D$8 -> 0.24284746 | E19: =E7/$E$8 -> 0.28725717 | F19: =F7/$F$8 -> 0.27342387
B20: Total | D20: =D8/$D$8 -> 1 | E20: =E8/$E$8 -> 1 | F20: =F8/$F$8 -> 1
B21: Chinese | C21: Sulwha 50cl bottle | D21: =D9/$D$12 -> 0.037598963 | E21: =E9/$E$12 -> 0.037423552 | F21: =F9/$F$12 -> 0.040173025
C22: Harbin 50cl & 64cl bottle | D22: =D10/$D$12 -> 0.2110553 | E22: =E10/$E$12 -> 0.18881384 | F22: =F10/$F$12 -> 0.21140306
C23: Tsingtao 64cl bottle | D23: =D11/$D$12 -> 0.75134574 | E23: =E11/$E$12 -> 0.77376261 | F23: =F11/$F$12 -> 0.74842391
B24: Total | D24: =D12/$D$12 -> 1 | E24: =E12/$E$12 -> 1 | F24: =F12/$F$12 -> 1
B26: 2. Draught market (Sales volume) | P26: [단위:케이스]
C27: SKU | D27: Y2025 | E27: Jan'26 | F27: Feb'26 | G27: Mar'26 | H27: Apr'26 | I27: May'26 | J27: Jun'26 | K27: Jul'26 | L27: Aug'26 | M27: Sep'26 | N27: Oct'26 | O27: Nov'26 | P27: Dec'26
B28: Lager | C28: Heineken 8L | D28: =서울!D16+부산!D16+대전!D16+대구!D16+광주!D16 -> 29787 | E28: =서울!E16+부산!E16+대전!E16+대구!E16+광주!E16 -> 1654 | F28: =서울!F16+부산!F16+대전!F16+대구!F16+광주!F16 -> 2004 | G28: =서울!G16+부산!G16+대전!G16+대구!G16+광주!G16 -> 0 | H28: =서울!H16+부산!H16+대전!H16+대구!H16+광주!H16 -> 0 | I28: =서울!I16+부산!I16+대전!I16+대구!I16+광주!I16 -> 0 | J28: =서울!J16+부산!J16+대전!J16+대구!J16+광주!J16 -> 0 | K28: =서울!K16+부산!K16+대전!K16+대구!K16+광주!K16 -> 0 | ... P28: =서울!P16+부산!P16+대전!P16+대구!P16+광주!P16 -> 0 | R28: =D28/68725 -> 0.43342306
C29: Heineken 20L | D29: =서울!D17+부산!D17+대전!D17+대구!D17+광주!D17 -> 27735 | E29: =서울!E17+부산!E17+대전!E17+대구!E17+광주!E17 -> 1188.5 | F29: =서울!F17+부산!F17+대전!F17+대구!F17+광주!F17 -> 1721 | G29: =서울!G17+부산!G17+대전!G17+대구!G17+광주!G17 -> 0 | H29: =서울!H17+부산!H17+대전!H17+대구!H17+광주!H17 -> 0 | I29: =서울!I17+부산!I17+대전!I17+대구!I17+광주!I17 -> 0 | J29: =서울!J17+부산!J17+대전!J17+대구!J17+광주!J17 -> 0 | K29: =서울!K17+부산!K17+대전!K17+대구!K17+광주!K17 -> 0 | ... P29: =서울!P17+부산!P17+대전!P17+대구!P17+광주!P17 -> 0 | R29: =D29/47990 -> 0.5779329
C30: Stellar 20L | D30: =서울!D18+부산!D18+대전!D18+대구!D18+광주!D18 -> 51522 | E30: =서울!E18+부산!E18+대전!E18+대구!E18+광주!E18 -> 3136 | F30: =서울!F18+부산!F18+대전!F18+대구!F18+광주!F18 -> 3044 | G30: =서울!G18+부산!G18+대전!G18+대구!G18+광주!G18 -> 0 | H30: =서울!H18+부산!H18+대전!H18+대구!H18+광주!H18 -> 0 | I30: =서울!I18+부산!I18+대전!I18+대구!I18+광주!I18 -> 0 | J30: =서울!J18+부산!J18+대전!J18+대구!J18+광주!J18 -> 0 | K30: =서울!K18+부산!K18+대전!K18+대구!K18+광주!K18 -> 0 | ... P30: =서울!P18+부산!P18+대전!P18+대구!P18+광주!P18 -> 0
C31: Asahi 10L & 19L | D31: =서울!D19+부산!D19+대전!D19+대구!D19+광주!D19 -> 49801 | E31: =서울!E19+부산!E19+대전!E19+대구!E19+광주!E19 -> 3388 | F31: =서울!F19+부산!F19+대전!F19+대구!F19+광주!F19 -> 3999 | G31: =서울!G19+부산!G19+대전!G19+대구!G19+광주!G19 -> 0 | H31: =서울!H19+부산!H19+대전!H19+대구!H19+광주!H19 -> 0 | I31: =서울!I19+부산!I19+대전!I19+대구!I19+광주!I19 -> 0 | J31: =서울!J19+부산!J19+대전!J19+대구!J19+광주!J19 -> 0 | K31: =서울!K19+부산!K19+대전!K19+대구!K19+광주!K19 -> 0 | ... P31: =서울!P19+부산!P19+대전!P19+대구!P19+광주!P19 -> 0
B32: Wheat | C32: Paulaner 20L | D32: =서울!D21+부산!D21+대전!D21+대구!D21+광주!D21 -> 0 | E32: =서울!E21+부산!E21+대전!E21+대구!E21+광주!E21 -> 0 | F32: =서울!F21+부산!F21+대전!F21+대구!F21+광주!F21 -> 0 | G32: =서울!G21+부산!G21+대전!G21+대구!G21+광주!G21 -> 0 | H32: =서울!H21+부산!H21+대전!H21+대구!H21+광주!H21 -> 0 | I32: =서울!I21+부산!I21+대전!I21+대구!I21+광주!I21 -> 0 | J32: =서울!J21+부산!J21+대전!J21+대구!J21+광주!J21 -> 0 | K32: =서울!K21+부산!K21+대전!K21+대구!K21+광주!K21 -> 0 | ... P32: =서울!P21+부산!P21+대전!P21+대구!P21+광주!P21 -> 0
C33: Hoegaarden 20L | D33: =서울!D22+부산!D22+대전!D22+대구!D22+광주!D22 -> 0 | E33: =서울!E22+부산!E22+대전!E22+대구!E22+광주!E22 -> 0 | F33: =서울!F22+부산!F22+대전!F22+대구!F22+광주!F22 -> 0 | G33: =서울!G22+부산!G22+대전!G22+대구!G22+광주!G22 -> 0 | H33: =서울!H22+부산!H22+대전!H22+대구!H22+광주!H22 -> 0 | I33: =서울!I22+부산!I22+대전!I22+대구!I22+광주!I22 -> 0 | J33: =서울!J22+부산!J22+대전!J22+대구!J22+광주!J22 -> 0 | K33: =서울!K22+부산!K22+대전!K22+대구!K22+광주!K22 -> 0 | ... P33: =서울!P22+부산!P22+대전!P22+대구!P22+광주!P22 -> 0
C34: Blanc 20L & 30L | D34: =서울!D23+부산!D23+대전!D23+대구!D23+광주!D23 -> 7150 | E34: =서울!E23+부산!E23+대전!E23+대구!E23+광주!E23 -> 466 | F34: =서울!F23+부산!F23+대전!F23+대구!F23+광주!F23 -> 429 | G34: =서울!G23+부산!G23+대전!G23+대구!G23+광주!G23 -> 0 | H34: =서울!H23+부산!H23+대전!H23+대구!H23+광주!H23 -> 0 | I34: =서울!I23+부산!I23+대전!I23+대구!I23+광주!I23 -> 0 | J34: =서울!J23+부산!J23+대전!J23+대구!J23+광주!J23 -> 0 | K34: =서울!K23+부산!K23+대전!K23+대구!K23+광주!K23 -> 0 | ... P34: =서울!P23+부산!P23+대전!P23+대구!P23+광주!P23 -> 0
C35: Total | D35: =서울!D20+부산!D21+대전!D21+대구!D21+광주!D21 -> 102047 | E35: =서울!E20+부산!E21+대전!E21+대구!E21+광주!E21 -> 5907 | F35: =서울!F20+부산!F21+대전!F21+대구!F21+광주!F21 -> 7312 | G35: =서울!G20+부산!G21+대전!G21+대구!G21+광주!G21 -> 0 | H35: =서울!H20+부산!H21+대전!H21+대구!H21+광주!H21 -> 0 | I35: =서울!I20+부산!I21+대전!I21+대구!I21+광주!I21 -> 0 | J35: =서울!J20+부산!J21+대전!J21+대구!J21+광주!J21 -> 0 | K35: =서울!K20+부산!K21+대전!K21+대구!K21+광주!K21 -> 0 | ... P35: =서울!P20+부산!P21+대전!P21+대구!P21+광주!P21 -> 0
B37: 2-1. Draught market (Market share) | P37: [단위:케이스]
C38: SKU | D38: Y2025 | E38: Jan'26 | F38: Feb'26 | G38: Mar'26 | H38: Apr'26 | I38: May'26 | J38: Jun'26 | K38: Jul'26 | L38: Aug'26 | M38: Sep'26 | N38: Oct'26 | O38: Nov'26 | P38: Dec'26
B39: Draught | C39: Heineken 8L | D39: =D28/$D$35 -> 0.29189491 | E39: =E28/$E$35 -> 0.28000677 | F39: =F28/$F$35 -> 0.27407002
C40: Heineken 20L | D40: =D29/$D$35 -> 0.27178653 | E40: =E29/$E$35 -> 0.20120196 | F40: =F29/$F$35 -> 0.23536652
C41: Stellar 20L | D41: =D30/$D$35 -> 0.504885 | E41: =E30/$E$35 -> 0.53089555 | F41: =F30/$F$35 -> 0.41630197
C42: Asahi 10L & 19L | D42: =D31/$D$35 -> 0.48802023 | E42: =E31/$E$35 -> 0.5735568 | F42: =F31/$F$35 -> 0.54690919
B43: Wheat | C43: Paulaner 20L | D43: =D32/$D$35 -> 0 | E43: =E32/$E$35 -> 0 | F43: =F32/$F$35 -> 0
C44: Hoegaarden 20L | D44: =D33/$D$35 -> 0 | E44: =E33/$E$35 -> 0 | F44: =F33/$F$35 -> 0
...

Sheet 월별 weight
C2: total | D2: Jan | E2: Feb | F2: Mar | G2: Apr | H2: May | I2: Jun | J2: Jul | K2: Aug | L2: Sep | M2: Oct | N2: Nov | O2: Dec
B3: Western | C3: 223682 | D3: =$C$3*D10 -> 0 | E3: =$C$3*E10 -> 0 | F3: =$C$3*F10 -> 0 | G3: =$C$3*G10 -> 0 | H3: =$C$3*H10 -> 0 | I3: =$C$3*I10 -> 0 | J3: =$C$3*J10 -> 0 | K3: =$C$3*K10 -> 0 | ... O3: =$C$3*O10 -> 0
B4: Chinease | C4: 223635 | D4: =$C$4*D10 -> 0 | E4: =$C$4*E10 -> 0 | F4: =$C$4*F10 -> 0 | G4: =$C$4*G10 -> 0 | H4: =$C$4*H10 -> 0 | I4: =$C$4*I10 -> 0 | J4: =$C$4*J10 -> 0 | K4: =$C$4*K10 -> 0 | ... O4: =$C$4*O10 -> 0
B5: Draught | C5: 148896 | D5: =$C$5*D10 -> 0 | E5: =$C$5*E10 -> 0 | F5: =$C$5*F10 -> 0 | G5: =$C$5*G10 -> 0 | H5: =$C$5*H10 -> 0 | I5: =$C$5*I10 -> 0 | J5: =$C$5*J10 -> 0 | K5: =$C$5*K10 -> 0 | ... O5: =$C$5*O10 -> 0
B8: HKR | C8: 41798 | D8: 1812.0121 | E8: 2191.3263 | F8: 2913.9911 | G8: 4034.6103 | H8: 4269.0682 | I8: 4471.9677 | J8: 3994.9388 | K8: 3972.3219 | L8: 3938.4555 | M8: 3491.0807 | N8: 3206.8792 | O8: 3501.5538
D9: =D8/$C8 -> 0.043351646 | E9: =E8/$C8 -> 0.052426583 | F9: =F8/$C8 -> 0.069716041 | G9: =G8/$C8 -> 0.096526396 | H9: =H8/$C8 -> 0.10213571 | I9: =I8/$C8 -> 0.10698999 | J9: =J8/$C8 -> 0.095577272 | K9: =K8/$C8 -> 0.095036171 | ... O9: =O8/$C8 -> 0.083773237
B10: ABI | D10: 0 | E10: 0 | F10: 0 | G10: 0 | H10: 0 | I10: 0 | J10: 0 | K10: 0 | L10: 0 | M10: 0 | N10: 0 | O10: 0

Sheet 서울
B2: 1. Bottle market | P2: [단위:QTY] | R2: 3. WS List (22)
C3: SKU | D3: Y2025 | E3: Jan'26 | F3: Feb'26 | G3: Mar'26 | H3: Apr'26 | I3: May'26 | J3: Jun'26 | K3: Jul'26 | L3: Aug'26 | M3: Sep'26 | N3: Oct'26 | O3: Nov'26 | P3: Dec'26 | R3: WS | S3: SKU | T3: Y2025 | U3: Jan'26 | V3: Feb'26 | W3: Mar'26 | X3: Apr'26 | Y3: May'26 | Z3: Jun'26 | AA3: Jul'26 | AB3: Aug'26 | AC3: Sep'26 | AD3: Oct'26 | AE3: Nov'26 | AF3: Dec'26
B4: Western | C4: Heineken 33cl bottle | D4: =SUMIF($S:$S,$C4,T:T) -> 30389 | E4: =SUMIF($S:$S,$C4,U:U) -> 583 | F4: =SUMIF($S:$S,$C4,V:V) -> 1538 | G4: =SUMIF($S:$S,$C4,W:W) -> 0 | H4: =SUMIF($S:$S,$C4,X:X) -> 0 | I4: =SUMIF($S:$S,$C4,Y:Y) -> 0 | J4: =SUMIF($S:$S,$C4,Z:Z) -> 0 | K4: =SUMIF($S:$S,$C4,AA:AA) -> 0 | L4: =SUMIF($S:$S,$C4,AB:AB) -> 0 | M4: =SUMIF($S:$S,$C4,AC:AC) -> 0 | N4: =SUMIF($S:$S,$C4,AD:AD) -> 0 | O4: =SUMIF($S:$S,$C4,AE:AE) -> 0 | P4: =SUMIF($S:$S,$C4,AF:AF) -> 0 | R4: 원천종합 | S4: Heineken 33cl bottle | T4: 689 | U4: 0 | V4: 0
C5: Stellar 33cl bottle | D5: =SUMIF($S:$S,$C5,T:T) -> 25163 | E5: =SUMIF($S:$S,$C5,U:U) -> 1611 | F5: =SUMIF($S:$S,$C5,V:V) -> 1759 | G5: =SUMIF($S:$S,$C5,W:W) -> 0 | H5: =SUMIF($S:$S,$C5,X:X) -> 0 | I5: =SUMIF($S:$S,$C5,Y:Y) -> 0 | J5: =SUMIF($S:$S,$C5,Z:Z) -> 0 | K5: =SUMIF($S:$S,$C5,AA:AA) -> 0 | L5: =SUMIF($S:$S,$C5,AB:AB) -> 0 | M5: =SUMIF($S:$S,$C5,AC:AC) -> 0 | N5: =SUMIF($S:$S,$C5,AD:AD) -> 0 | O5: =SUMIF($S:$S,$C5,AE:AE) -> 0 | P5: =SUMIF($S:$S,$C5,AF:AF) -> 0 | R5: 원천종합 | S5: Stellar 33cl bottle | T5: 2000 | U5: 130 | V5: 170
C6: Bud 33cl bottle | D6: =SUMIF($S:$S,$C6,T:T) -> 89609 | E6: =SUMIF($S:$S,$C6,U:U) -> 4935 | F6: =SUMIF($S:$S,$C6,V:V) -> 5394 | G6: =SUMIF($S:$S,$C6,W:W) -> 0 | H6: =SUMIF($S:$S,$C6,X:X) -> 0 | I6: =SUMIF($S:$S,$C6,Y:Y) -> 0 | J6: =SUMIF($S:$S,$C6,Z:Z) -> 0 | K6: =SUMIF($S:$S,$C6,AA:AA) -> 0 | L6: =SUMIF($S:$S,$C6,AB:AB) -> 0 | M6: =SUMIF($S:$S,$C6,AC:AC) -> 0 | N6: =SUMIF($S:$S,$C6,AD:AD) -> 0 | O6: =SUMIF($S:$S,$C6,AE:AE) -> 0 | P6: =SUMIF($S:$S,$C6,AF:AF) -> 0 | R6: 원천종합 | S6: Bud 33cl bottle | T6: 3500 | U6: 100 | V6: 130
C7: Corona 33cl bottle | D7: =SUMIF($S:$S,$C7,T:T) -> 46753 | E7: =SUMIF($S:$S,$C7,U:U) -> 3282 | F7: =SUMIF($S:$S,$C7,V:V) -> 3575 | G7: =SUMIF($S:$S,$C7,W:W) -> 0 | H7: =SUMIF($S:$S,$C7,X:X) -> 0 | I7: =SUMIF($S:$S,$C7,Y:Y) -> 0 | J7: =SUMIF($S:$S,$C7,Z:Z) -> 0 | K7: =SUMIF($S:$S,$C7,AA:AA) -> 0 | L7: =SUMIF($S:$S,$C7,AB:AB) -> 0 | M7: =SUMIF($S:$S,$C7,AC:AC) -> 0 | N7: =SUMIF($S:$S,$C7,AD:AD) -> 0 | O7: =SUMIF($S:$S,$C7,AE:AE) -> 0 | P7: =SUMIF($S:$S,$C7,AF:AF) -> 0 | R7: 원천종합 | S7: Corona 33cl bottle | T7: 360 | U7: 30 | V7: 80
B8: Total | D8: =SUM(D4:D7) -> 191914 | E8: =SUM(E4:E7) -> 10411 | F8: =SUM(F4:F7) -> 12266 | G8: =SUM(G4:G7) -> 0 | H8: =SUM(H4:H7) -> 0 | I8: =SUM(I4:I7) -> 0 | J8: =SUM(J4:J7) -> 0 | K8: =SUM(K4:K7) -> 0 | ... P8: =SUM(P4:P7) -> 0 | R8: 원천종합 | S8: Sulwha 50cl bottle | T8: 2 | U8: 0 | V8: 0
B9: Chinese | C9: Sulwha 50cl bottle | D9: =SUMIF($S:$S,$C9,T:T) -> 6319 | E9: =SUMIF($S:$S,$C9,U:U) -> 508 | F9: =SUMIF($S:$S,$C9,V:V) -> 620 | G9: =SUMIF($S:$S,$C9,W:W) -> 0 | H9: =SUMIF($S:$S,$C9,X:X) -> 0 | I9: =SUMIF($S:$S,$C9,Y:Y) -> 0 | J9: =SUMIF($S:$S,$C9,Z:Z) -> 0 | K9: =SUMIF($S:$S,$C9,AA:AA) -> 0 | L9: =SUMIF($S:$S,$C9,AB:AB) -> 0 | M9: =SUMIF($S:$S,$C9,AC:AC) -> 0 | N9: =SUMIF($S:$S,$C9,AD:AD) -> 0 | O9: =SUMIF($S:$S,$C9,AE:AE) -> 0 | P9: =SUMIF($S:$S,$C9,AF:AF) -> 0 | R9: 원천종합 | S9: Harbin 50cl & 64cl bottle | T9: 0 | U9: 0 | V9: 0
C10: Harbin 50cl & 64cl bottle | D10: =SUMIF($S:$S,$C10,T:T) -> 41531 | E10: =SUMIF($S:$S,$C10,U:U) -> 3103 | F10: =SUMIF($S:$S,$C10,V:V) -> 3760 | G10: =SUMIF($S:$S,$C10,W:W) -> 0 | H10: =SUMIF($S:$S,$C10,X:X) -> 0 | I10: =SUMIF($S:$S,$C10,Y:Y) -> 0 | J10: =SUMIF($S:$S,$C10,Z:Z) -> 0 | K10: =SUMIF($S:$S,$C10,AA:AA) -> 0 | L10: =SUMIF($S:$S,$C10,AB:AB) -> 0 | M10: =SUMIF($S:$S,$C10,AC:AC) -> 0 | N10: =SUMIF($S:$S,$C10,AD:AD) -> 0 | O10: =SUMIF($S:$S,$C10,AE:AE) -> 0 | P10: =SUMIF($S:$S,$C10,AF:AF) -> 0 | R10: 원천종합 | S10: Tsingtao 64cl bottle | T10: 360 | U10: 40 | V10: 30
C11: Tsingtao 64cl bottle | D11: =SUMIF($S:$S,$C11,T:T) -> 136913 | E11: =SUMIF($S:$S,$C11,U:U) -> 12087 | F11: =SUMIF($S:$S,$C11,V:V) -> 12749 | G11: =SUMIF($S:$S,$C11,W:W) -> 0 | H11: =SUMIF($S:$S,$C11,X:X) -> 0 | I11: =SUMIF($S:$S,$C11,Y:Y) -> 0 | J11: =SUMIF($S:$S,$C11,Z:Z) -> 0 | K11: =SUMIF($S:$S,$C11,AA:AA) -> 0 | L11: =SUMIF($S:$S,$C11,AB:AB) -> 0 | M11: =SUMIF($S:$S,$C11,AC:AC) -> 0 | N11: =SUMIF($S:$S,$C11,AD:AD) -> 0 | O11: =SUMIF($S:$S,$C11,AE:AE) -> 0 | P11: =SUMIF($S:$S,$C11,AF:AF) -> 0 | R11: 원천종합 | S11: Heineken 8L | T11: 83 | U11: 90 | V11: 0
B12: Total | D12: =SUM(D9:D11) -> 184763 | E12: =SUM(E9:E11) -> 15698 | F12: =SUM(F9:F11) -> 17129 | G12: =SUM(G9:G11) -> 0 | H12: =SUM(H9:H11) -> 0 | I12: =SUM(I9:I11) -> 0 | J12: =SUM(J9:J11) -> 0 | K12: =SUM(K9:K11) -> 0 | ... P12: =SUM(P9:P11) -> 0 | R12: 원천종합 | S12: Heineken 20L | T12: 2043 | U12: 208 | V12: 592
R13: 원천종합 | S13: Stellar 12L & 20L | T13: 7000 | U13: 400 | V13: 380
B14: 2. Draught market | P14: [단위:QTY] | R14: 원천종합 | S14: Asahi 10L & 19L | T14: 390 | U14: 20 | V14: 70
C15: SKU | D15: Y2025 | E15: Jan'26 | F15: Feb'26 | G15: Mar'26 | H15: Apr'26 | I15: May'26 | J15: Jun'26 | K15: Jul'26 | L15: Aug'26 | M15: Sep'26 | N15: Oct'26 | O15: Nov'26 | P15: Dec'26 | R15: 원천종합 | S15: Paulaner 20L
B16: Lager | C16: Heineken 8L | D16: =SUMIF($S:$S,$C16,T:T) -> 20391 | E16: =SUMIF($S:$S,$C16,U:U) -> 1064 | F16: =SUMIF($S:$S,$C16,V:V) -> 1406 | G16: =SUMIF($S:$S,$C16,W:W) -> 0 | H16: =SUMIF($S:$S,$C16,X:X) -> 0 | I16: =SUMIF($S:$S,$C16,Y:Y) -> 0 | J16: =SUMIF($S:$S,$C16,Z:Z) -> 0 | K16: =SUMIF($S:$S,$C16,AA:AA) -> 0 | L16: =SUMIF($S:$S,$C16,AB:AB) -> 0 | M16: =SUMIF($S:$S,$C16,AC:AC) -> 0 | N16: =SUMIF($S:$S,$C16,AD:AD) -> 0 | O16: =SUMIF($S:$S,$C16,AE:AE) -> 0 | P16: =SUMIF($S:$S,$C16,AF:AF) -> 0 | R16: 원천종합 | S16: Hoegaarden 20L
C17: Heineken 20L | D17: =SUMIF($S:$S,$C17,T:T) -> 13951 | E17: =SUMIF($S:$S,$C17,U:U) -> 601 | F17: =SUMIF($S:$S,$C17,V:V) -> 1100 | G17: =SUMIF($S:$S,$C17,W:W) -> 0 | H17: =SUMIF($S:$S,$C17,X:X) -> 0 | I17: =SUMIF($S:$S,$C17,Y:Y) -> 0 | J17: =SUMIF($S:$S,$C17,Z:Z) -> 0 | K17: =SUMIF($S:$S,$C17,AA:AA) -> 0 | L17: =SUMIF($S:$S,$C17,AB:AB) -> 0 | M17: =SUMIF($S:$S,$C17,AC:AC) -> 0 | N17: =SUMIF($S:$S,$C17,AD:AD) -> 0 | O17: =SUMIF($S:$S,$C17,AE:AE) -> 0 | P17: =SUMIF($S:$S,$C17,AF:AF) -> 0 | R17: 원천종합 | S17: Blanc 20L & 30L | T17: 300 | U17: 20 | V17: 50
C18: Stellar 12L & 20L | D18: =SUMIF($S:$S,$C18,T:T) -> 40496 | E18: =SUMIF($S:$S,$C18,U:U) -> 2511 | F18: =SUMIF($S:$S,$C18,V:V) -> 2313 | G18: =SUMIF($S:$S,$C18,W:W) -> 0 | H18: =SUMIF($S:$S,$C18,X:X) -> 0 | I18: =SUMIF($S:$S,$C18,Y:Y) -> 0 | J18: =SUMIF($S:$S,$C18,Z:Z) -> 0 | K18: =SUMIF($S:$S,$C18,AA:AA) -> 0 | L18: =SUMIF($S:$S,$C18,AB:AB) -> 0 | M18: =SUMIF($S:$S,$C18,AC:AC) -> 0 | N18: =SUMIF($S:$S,$C18,AD:AD) -> 0 | O18: =SUMIF($S:$S,$C18,AE:AE) -> 0 | P18: =SUMIF($S:$S,$C18,AF:AF) -> 0
C19: Asahi 10L & 19L | D19: =SUMIF($S:$S,$C19,T:T) -> 27209 | E19: =SUMIF($S:$S,$C19,U:U) -> 1731 | F19: =SUMIF($S:$S,$C19,V:V) -> 2493 | G19: =SUMIF($S:$S,$C19,W:W) -> 0 | H19: =SUMIF($S:$S,$C19,X:X) -> 0 | I19: =SUMIF($S:$S,$C19,Y:Y) -> 0 | J19: =SUMIF($S:$S,$C19,Z:Z) -> 0 | K19: =SUMIF($S:$S,$C19,AA:AA) -> 0 | L19: =SUMIF($S:$S,$C19,AB:AB) -> 0 | M19: =SUMIF($S:$S,$C19,AC:AC) -> 0 | N19: =SUMIF($S:$S,$C19,AD:AD) -> 0 | O19: =SUMIF($S:$S,$C19,AE:AE) -> 0 | P19: =SUMIF($S:$S,$C19,AF:AF) -> 0 | R19: WS | S19: SKU | T19: Y2025 | U19: Jan'26 | V19: Feb'26 | W19: Mar'26 | X19: Apr'26 | Y19: May'26 | Z19: Jun'26 | AA19: Jul'26 | AB19: Aug'26 | AC19: Sep'26 | AD19: Oct'26 | AE19: Nov'26 | AF19: Dec'26
C20: Total | D20: =SUM(D16:D19) -> 102047 | E20: =SUM(E16:E19) -> 5907 | F20: =SUM(F16:F19) -> 7312 | G20: =SUM(G16:G19) -> 0 | H20: =SUM(H16:H19) -> 0 | I20: =SUM(I16:I19) -> 0 | J20: =SUM(J16:J19) -> 0 | K20: =SUM(K16:K19) -> 0 | ... P20: =SUM(P16:P19) -> 0 | R20: 중앙종합 | S20: Heineken 33cl bottle | T20: 1614 | U20: 0 | V20: 10
B21: Wheat | C21: Paulaner 20L | D21: =SUMIF($S:$S,$C21,T:T) -> 0 | E21: =SUMIF($S:$S,$C21,U:U) -> 0 | F21: =SUMIF($S:$S,$C21,V:V) -> 0 | G21: =SUMIF($S:$S,$C21,W:W) -> 0 | H21: =SUMIF($S:$S,$C21,X:X) -> 0 | I21: =SUMIF($S:$S,$C21,Y:Y) -> 0 | J21: =SUMIF($S:$S,$C21,Z:Z) -> 0 | K21: =SUMIF($S:$S,$C21,AA:AA) -> 0 | L21: =SUMIF($S:$S,$C21,AB:AB) -> 0 | M21: =SUMIF($S:$S,$C21,AC:AC) -> 0 | N21: =SUMIF($S:$S,$C21,AD:AD) -> 0 | O21: =SUMIF($S:$S,$C21,AE:AE) -> 0 | P21: =SUMIF($S:$S,$C21,AF:AF) -> 0 | R21: 중앙종합 | S21: Stellar 33cl bottle | T21: 1600 | U21: 120 | V21: 200
C22: Hoegaarden 20L | D22: =SUMIF($S:$S,$C22,T:T) -> 0 | E22: =SUMIF($S:$S,$C22,U:U) -> 0 | F22: =SUMIF($S:$S,$C22,V:V) -> 0 | G22: =SUMIF($S:$S,$C22,W:W) -> 0 | H22: =SUMIF($S:$S,$C22,X:X) -> 0 | I22: =SUMIF($S:$S,$C22,Y:Y) -> 0 | J22: =SUMIF($S:$S,$C22,Z:Z) -> 0 | K22: =SUMIF($S:$S,$C22,AA:AA) -> 0 | L22: =SUMIF($S:$S,$C22,AB:AB) -> 0 | M22: =SUMIF($S:$S,$C22,AC:AC) -> 0 | N22: =SUMIF($S:$S,$C22,AD:AD) -> 0 | O22: =SUMIF($S:$S,$C22,AE:AE) -> 0 | P22: =SUMIF($S:$S,$C22,AF:AF) -> 0 | R22: 중앙종합 | S22: Bud 33cl bottle | T22: 2700 | U22: 200 | V22: 240
C23: Blanc 20L & 30L | D23: =SUMIF($S:$S,$C23,T:T) -> 3494 | E23: =SUMIF($S:$S,$C23,U:U) -> 229 | F23: =SUMIF($S:$S,$C23,V:V) -> 318 | G23: =SUMIF($S:$S,$C23,W:W) -> 0 | H23: =SUMIF($S:$S,$C23,X:X) -> 0 | I23: =SUMIF($S:$S,$C23,Y:Y) -> 0 | J23: =SUMIF($S:$S,$C23,Z:Z) -> 0 | K23: =SUMIF($S:$S,$C23,AA:AA) -> 0 | L23: =SUMIF($S:$S,$C23,AB:AB) -> 0 | M23: =SUMIF($S:$S,$C23,AC:AC) -> 0 | N23: =SUMIF($S:$S,$C23,AD:AD) -> 0 | O23: =SUMIF($S:$S,$C23,AE:AE) -> 0 | P23: =SUMIF($S:$S,$C23,AF:AF) -> 0 | R23: 중앙종합 | S23: Corona 33cl bottle | T23: 2200 | U23: 160 | V23: 180
C24: Total | D24: =SUM(D21:D23) -> 3494 | E24: =SUM(E21:E23) -> 229 | F24: =SUM(F21:F23) -> 318 | G24: =SUM(G21:G23) -> 0 | H24: =SUM(H21:H23) -> 0 | I24: =SUM(I21:I23) -> 0 | J24: =SUM(J21:J23) -> 0 | K24: =SUM(K21:K23) -> 0 | ... P24: =SUM(P21:P23) -> 0 | R24: 중앙종합 | S24: Sulwha 50cl bottle | T24: 30 | U24: 0 | V24: 0
R25: 중앙종합 | S25: Harbin 50cl & 64cl bottle | T25: 480 | U25: 40 | V25: 60
R26: 중앙종합 | S26: Tsingtao 64cl bottle | T26: 3300 | U26: 250 | V26: 400
R27: 중앙종합 | S27: Heineken 8L | T27: 435 | U27: 24 | V27: 34
R28: 중앙종합 | S28: Heineken 20L | T28: 1515 | U28: 48 | V28: 0
R29: 중앙종합 | S29: Stellar 12L & 20L | T29: 1700 | U29: 120 | V29: 140
R30: 중앙종합 | S30: Asahi 10L & 19L | T30: 800 | U30: 60 | V30: 80
R31: 중앙종합 | S31: Paulaner 20L
R32: 중앙종합 | S32: Hoegaarden 20L
R33: 중앙종합 | S33: Blanc 20L & 30L | T33: 300 | U33: 20 | V33: 27
R35: WS | S35: SKU | T35: Y2025 | U35: Jan'26 | V35: Feb'26 | W35: Mar'26 | X35: Apr'26 | Y35: May'26 | Z35: Jun'26 | AA35: Jul'26 | AB35: Aug'26 | AC35: Sep'26 | AD35: Oct'26 | AE35: Nov'26 | AF35: Dec'26
R36: 신합상사 | S36: Heineken 33cl bottle | T36: 1430 | U36: 0 | V36: 90
R37: 신합상사 | S37: Stellar 33cl bottle | T37: 2800 | U37: 240 | V37: 320
R38: 신합상사 | S38: Bud 33cl bottle | T38: 4500 | U38: 300 | V38: 400
R39: 신합상사 | S39: Corona 33cl bottle | T39: 2800 | U39: 200 | V39: 300
R40: 신합상사 | S40: Sulwha 50cl bottle | T40: 70 | U40: 0 | V40: 0
R41: 신합상사 | S41: Harbin 50cl & 64cl bottle | T41: 120 | U41: 10 | V41: 0
R42: 신합상사 | S42: Tsingtao 64cl bottle | T42: 1400 | U42: 100 | V42: 120
...

Sheet 부산
B2: 1. Bottle market | P2: [단위:QTY] | R2: 3. WS List
C3: SKU | D3: Y2025 | E3: Jan'26 | F3: Feb'26 | G3: Mar'26 | H3: Apr'26 | I3: May'26 | J3: Jun'26 | K3: Jul'26 | L3: Aug'26 | M3: Sep'26 | N3: Oct'26 | O3: Nov'26 | P3: Dec'26 | R3: WS | S3: SKU | T3: Y2025 | U3: Jan'26 | V3: Feb'26 | W3: Mar'26 | X3: Apr'26 | Y3: May'26 | Z3: Jun'26 | AA3: Jul'26 | AB3: Aug'26 | AC3: Sep'26 | AD3: Oct'26 | AE3: Nov'26 | AF3: Dec'26
B4: Western | C4: Heineken 33cl bottle | D4: =SUMIF($S:$S,$C4,T:T) -> 9348 | E4: =SUMIF($S:$S,$C4,U:U) -> 748 | F4: =SUMIF($S:$S,$C4,V:V) -> 798 | G4: =SUMIF($S:$S,$C4,W:W) -> 0 | H4: =SUMIF($S:$S,$C4,X:X) -> 0 | I4: =SUMIF($S:$S,$C4,Y:Y) -> 0 | J4: =SUMIF($S:$S,$C4,Z:Z) -> 0 | K4: =SUMIF($S:$S,$C4,AA:AA) -> 0 | L4: =SUMIF($S:$S,$C4,AB:AB) -> 0 | M4: =SUMIF($S:$S,$C4,AC:AC) -> 0 | N4: =SUMIF($S:$S,$C4,AD:AD) -> 0 | O4: =SUMIF($S:$S,$C4,AE:AE) -> 0 | P4: =SUMIF($S:$S,$C4,AF:AF) -> 0 | R4: 부성주류㈜ | S4: Heineken 33cl bottle | T4: 492 | U4: 22 | V4: 29
C5: Stellar 33cl bottle | D5: =SUMIF($S:$S,$C5,T:T) -> 1414 | E5: =SUMIF($S:$S,$C5,U:U) -> 91 | F5: =SUMIF($S:$S,$C5,V:V) -> 90 | G5: =SUMIF($S:$S,$C5,W:W) -> 0 | H5: =SUMIF($S:$S,$C5,X:X) -> 0 | I5: =SUMIF($S:$S,$C5,Y:Y) -> 0 | J5: =SUMIF($S:$S,$C5,Z:Z) -> 0 | K5: =SUMIF($S:$S,$C5,AA:AA) -> 0 | L5: =SUMIF($S:$S,$C5,AB:AB) -> 0 | M5: =SUMIF($S:$S,$C5,AC:AC) -> 0 | N5: =SUMIF($S:$S,$C5,AD:AD) -> 0 | O5: =SUMIF($S:$S,$C5,AE:AE) -> 0 | P5: =SUMIF($S:$S,$C5,AF:AF) -> 0 | R5: 부성주류㈜ | S5: Stellar 33cl bottle | T5: 85 | U5: 6 | V5: 8
C6: Bud 33cl bottle | D6: =SUMIF($S:$S,$C6,T:T) -> 3775 | E6: =SUMIF($S:$S,$C6,U:U) -> 254 | F6: =SUMIF($S:$S,$C6,V:V) -> 381 | G6: =SUMIF($S:$S,$C6,W:W) -> 0 | H6: =SUMIF($S:$S,$C6,X:X) -> 0 | I6: =SUMIF($S:$S,$C6,Y:Y) -> 0 | J6: =SUMIF($S:$S,$C6,Z:Z) -> 0 | K6: =SUMIF($S:$S,$C6,AA:AA) -> 0 | L6: =SUMIF($S:$S,$C6,AB:AB) -> 0 | M6: =SUMIF($S:$S,$C6,AC:AC) -> 0 | N6: =SUMIF($S:$S,$C6,AD:AD) -> 0 | O6: =SUMIF($S:$S,$C6,AE:AE) -> 0 | P6: =SUMIF($S:$S,$C6,AF:AF) -> 0 | R6: 부성주류㈜ | S6: Bud 33cl bottle | T6: 593 | U6: 39 | V6: 59
C7: Corona 33cl bottle | D7: =SUMIF($S:$S,$C7,T:T) -> 8207 | E7: =SUMIF($S:$S,$C7,U:U) -> 519 | F7: =SUMIF($S:$S,$C7,V:V) -> 544 | G7: =SUMIF($S:$S,$C7,W:W) -> 0 | H7: =SUMIF($S:$S,$C7,X:X) -> 0 | I7: =SUMIF($S:$S,$C7,Y:Y) -> 0 | J7: =SUMIF($S:$S,$C7,Z:Z) -> 0 | K7: =SUMIF($S:$S,$C7,AA:AA) -> 0 | L7: =SUMIF($S:$S,$C7,AB:AB) -> 0 | M7: =SUMIF($S:$S,$C7,AC:AC) -> 0 | N7: =SUMIF($S:$S,$C7,AD:AD) -> 0 | O7: =SUMIF($S:$S,$C7,AE:AE) -> 0 | P7: =SUMIF($S:$S,$C7,AF:AF) -> 0 | R7: 부성주류㈜ | S7: Corona 33cl bottle | T7: 610 | U7: 34 | V7: 58
B8: Total | D8: =SUM(D4:D7) -> 22744 | E8: =SUM(E4:E7) -> 1612 | F8: =SUM(F4:F7) -> 1813 | G8: =SUM(G4:G7) -> 0 | H8: =SUM(H4:H7) -> 0 | I8: =SUM(I4:I7) -> 0 | J8: =SUM(J4:J7) -> 0 | K8: =SUM(K4:K7) -> 0 | ... P8: =SUM(P4:P7) -> 0 | R8: 부성주류㈜ | S8: Sulwha 50cl bottle | T8: 20 | U8: 2 | V8: 7
B9: Chinese | C9: Sulwha 50cl bottle | D9: =SUMIF($S:$S,$C9,T:T) -> 357 | E9: =SUMIF($S:$S,$C9,U:U) -> 45 | F9: =SUMIF($S:$S,$C9,V:V) -> 54 | G9: =SUMIF($S:$S,$C9,W:W) -> 0 | H9: =SUMIF($S:$S,$C9,X:X) -> 0 | I9: =SUMIF($S:$S,$C9,Y:Y) -> 0 | J9: =SUMIF($S:$S,$C9,Z:Z) -> 0 | K9: =SUMIF($S:$S,$C9,AA:AA) -> 0 | L9: =SUMIF($S:$S,$C9,AB:AB) -> 0 | M9: =SUMIF($S:$S,$C9,AC:AC) -> 0 | N9: =SUMIF($S:$S,$C9,AD:AD) -> 0 | O9: =SUMIF($S:$S,$C9,AE:AE) -> 0 | P9: =SUMIF($S:$S,$C9,AF:AF) -> 0 | R9: 부성주류㈜ | S9: Harbin 50cl & 64cl bottle | T9: 260 | U9: 17 | V9: 24
C10: Harbin 50cl & 64cl bottle | D10: =SUMIF($S:$S,$C10,T:T) -> 4699 | E10: =SUMIF($S:$S,$C10,U:U) -> 284 | F10: =SUMIF($S:$S,$C10,V:V) -> 329 | G10: =SUMIF($S:$S,$C10,W:W) -> 0 | H10: =SUMIF($S:$S,$C10,X:X) -> 0 | I10: =SUMIF($S:$S,$C10,Y:Y) -> 0 | J10: =SUMIF($S:$S,$C10,Z:Z) -> 0 | K10: =SUMIF($S:$S,$C10,AA:AA) -> 0 | L10: =SUMIF($S:$S,$C10,AB:AB) -> 0 | M10: =SUMIF($S:$S,$C10,AC:AC) -> 0 | N10: =SUMIF($S:$S,$C10,AD:AD) -> 0 | O10: =SUMIF($S:$S,$C10,AE:AE) -> 0 | P10: =SUMIF($S:$S,$C10,AF:AF) -> 0 | R10: 부성주류㈜ | S10: Tsingtao 64cl bottle | T10: 701 | U10: 45 | V10: 34
C11: Tsingtao 64cl bottle | D11: =SUMIF($S:$S,$C11,T:T) -> 10221 | E11: =SUMIF($S:$S,$C11,U:U) -> 696 | F11: =SUMIF($S:$S,$C11,V:V) -> 765 | G11: =SUMIF($S:$S,$C11,W:W) -> 0 | H11: =SUMIF($S:$S,$C11,X:X) -> 0 | I11: =SUMIF($S:$S,$C11,Y:Y) -> 0 | J11: =SUMIF($S:$S,$C11,Z:Z) -> 0 | K11: =SUMIF($S:$S,$C11,AA:AA) -> 0 | L11: =SUMIF($S:$S,$C11,AB:AB) -> 0 | M11: =SUMIF($S:$S,$C11,AC:AC) -> 0 | N11: =SUMIF($S:$S,$C11,AD:AD) -> 0 | O11: =SUMIF($S:$S,$C11,AE:AE) -> 0 | P11: =SUMIF($S:$S,$C11,AF:AF) -> 0 | R11: 부성주류㈜ | S11: Heineken 8L | T11: 650 | U11: 43 | V11: 62
B12: Total | D12: =SUM(D9:D11) -> 15277 | E12: =SUM(E9:E11) -> 1025 | F12: =SUM(F9:F11) -> 1148 | G12: =SUM(G9:G11) -> 0 | H12: =SUM(H9:H11) -> 0 | I12: =SUM(I9:I11) -> 0 | J12: =SUM(J9:J11) -> 0 | K12: =SUM(K9:K11) -> 0 | ... P12: =SUM(P9:P11) -> 0 | R12: 부성주류㈜ | S12: Heineken 20L | T12: 212 | U12: 15 | V12: 12
R13: 부성주류㈜ | S13: Stellar 12L & 20L | T13: 1080 | U13: 69 | V13: 85
B14: 2. Draught market | P14: [단위:QTY] | R14: 부성주류㈜ | S14: Asahi 10L & 19L | T14: 410 | U14: 26 | V14: 39
C15: SKU | D15: Y2025 | E15: Jan'26 | F15: Feb'26 | G15: Mar'26 | H15: Apr'26 | I15: May'26 | J15: Jun'26 | K15: Jul'26 | L15: Aug'26 | M15: Sep'26 | N15: Oct'26 | O15: Nov'26 | P15: Dec'26 | R15: 부성주류㈜ | S15: Paulaner 20L
B16: Lager | C16: Heineken 8L | D16: =SUMIF($S:$S,$C16,T:T) -> 3662 | E16: =SUMIF($S:$S,$C16,U:U) -> 208 | F16: =SUMIF($S:$S,$C16,V:V) -> 274 | G16: =SUMIF($S:$S,$C16,W:W) -> 0 | H16: =SUMIF($S:$S,$C16,X:X) -> 0 | I16: =SUMIF($S:$S,$C16,Y:Y) -> 0 | J16: =SUMIF($S:$S,$C16,Z:Z) -> 0 | K16: =SUMIF($S:$S,$C16,AA:AA) -> 0 | L16: =SUMIF($S:$S,$C16,AB:AB) -> 0 | M16: =SUMIF($S:$S,$C16,AC:AC) -> 0 | N16: =SUMIF($S:$S,$C16,AD:AD) -> 0 | O16: =SUMIF($S:$S,$C16,AE:AE) -> 0 | P16: =SUMIF($S:$S,$C16,AF:AF) -> 0 | R16: 부성주류㈜ | S16: Hoegaarden 20L
C17: Heineken 20L | D17: =SUMIF($S:$S,$C17,T:T) -> 2865 | E17: =SUMIF($S:$S,$C17,U:U) -> 250 | F17: =SUMIF($S:$S,$C17,V:V) -> 200 | G17: =SUMIF($S:$S,$C17,W:W) -> 0 | H17: =SUMIF($S:$S,$C17,X:X) -> 0 | I17: =SUMIF($S:$S,$C17,Y:Y) -> 0 | J17: =SUMIF($S:$S,$C17,Z:Z) -> 0 | K17: =SUMIF($S:$S,$C17,AA:AA) -> 0 | L17: =SUMIF($S:$S,$C17,AB:AB) -> 0 | M17: =SUMIF($S:$S,$C17,AC:AC) -> 0 | N17: =SUMIF($S:$S,$C17,AD:AD) -> 0 | O17: =SUMIF($S:$S,$C17,AE:AE) -> 0 | P17: =SUMIF($S:$S,$C17,AF:AF) -> 0 | R17: 부성주류㈜ | S17: Blanc 20L & 30L | T17: 80 | U17: 5 | V17: 4
C18: Stellar 12L & 20L | D18: =SUMIF($S:$S,$C18,T:T) -> 2779 | E18: =SUMIF($S:$S,$C18,U:U) -> 171 | F18: =SUMIF($S:$S,$C18,V:V) -> 251 | G18: =SUMIF($S:$S,$C18,W:W) -> 0 | H18: =SUMIF($S:$S,$C18,X:X) -> 0 | I18: =SUMIF($S:$S,$C18,Y:Y) -> 0 | J18: =SUMIF($S:$S,$C18,Z:Z) -> 0 | K18: =SUMIF($S:$S,$C18,AA:AA) -> 0 | L18: =SUMIF($S:$S,$C18,AB:AB) -> 0 | M18: =SUMIF($S:$S,$C18,AC:AC) -> 0 | N18: =SUMIF($S:$S,$C18,AD:AD) -> 0 | O18: =SUMIF($S:$S,$C18,AE:AE) -> 0 | P18: =SUMIF($S:$S,$C18,AF:AF) -> 0
C19: Asahi 10L & 19L | D19: =SUMIF($S:$S,$C19,T:T) -> 5760 | E19: =SUMIF($S:$S,$C19,U:U) -> 401 | F19: =SUMIF($S:$S,$C19,V:V) -> 455 | G19: =SUMIF($S:$S,$C19,W:W) -> 0 | H19: =SUMIF($S:$S,$C19,X:X) -> 0 | I19: =SUMIF($S:$S,$C19,Y:Y) -> 0 | J19: =SUMIF($S:$S,$C19,Z:Z) -> 0 | K19: =SUMIF($S:$S,$C19,AA:AA) -> 0 | L19: =SUMIF($S:$S,$C19,AB:AB) -> 0 | M19: =SUMIF($S:$S,$C19,AC:AC) -> 0 | N19: =SUMIF($S:$S,$C19,AD:AD) -> 0 | O19: =SUMIF($S:$S,$C19,AE:AE) -> 0 | P19: =SUMIF($S:$S,$C19,AF:AF) -> 0 | R19: WS | S19: SKU | T19: Y2025 | U19: Jan'26 | V19: Feb'26 | W19: Mar'26 | X19: Apr'26 | Y19: May'26 | Z19: Jun'26 | AA19: Jul'26 | AB19: Aug'26 | AC19: Sep'26 | AD19: Oct'26 | AE19: Nov'26 | AF19: Dec'26
C20: Total | D20: =SUM(D16:D19) -> 15066 | E20: =SUM(E16:E19) -> 1030 | F20: =SUM(F16:F19) -> 1180 | G20: =SUM(G16:G19) -> 0 | H20: =SUM(H16:H19) -> 0 | I20: =SUM(I16:I19) -> 0 | J20: =SUM(J16:J19) -> 0 | K20: =SUM(K16:K19) -> 0 | ... P20: =SUM(P16:P19) -> 0 | R20: 동래상사㈜ | S20: Heineken 33cl bottle | T20: 345 | U20: 12 | V20: 27
B21: Wheat | C21: Paulaner 20L | D21: =SUMIF($S:$S,$C21,T:T) -> 0 | E21: =SUMIF($S:$S,$C21,U:U) -> 0 | F21: =SUMIF($S:$S,$C21,V:V) -> 0 | G21: =SUMIF($S:$S,$C21,W:W) -> 0 | H21: =SUMIF($S:$S,$C21,X:X) -> 0 | I21: =SUMIF($S:$S,$C21,Y:Y) -> 0 | J21: =SUMIF($S:$S,$C21,Z:Z) -> 0 | K21: =SUMIF($S:$S,$C21,AA:AA) -> 0 | L21: =SUMIF($S:$S,$C21,AB:AB) -> 0 | M21: =SUMIF($S:$S,$C21,AC:AC) -> 0 | N21: =SUMIF($S:$S,$C21,AD:AD) -> 0 | O21: =SUMIF($S:$S,$C21,AE:AE) -> 0 | P21: =SUMIF($S:$S,$C21,AF:AF) -> 0 | R21: 동래상사㈜ | S21: Stellar 33cl bottle | T21: 88 | U21: 6 | V21: 7
C22: Hoegaarden 20L | D22: =SUMIF($S:$S,$C22,T:T) -> 0 | E22: =SUMIF($S:$S,$C22,U:U) -> 0 | F22: =SUMIF($S:$S,$C22,V:V) -> 0 | G22: =SUMIF($S:$S,$C22,W:W) -> 0 | H22: =SUMIF($S:$S,$C22,X:X) -> 0 | I22: =SUMIF($S:$S,$C22,Y:Y) -> 0 | J22: =SUMIF($S:$S,$C22,Z:Z) -> 0 | K22: =SUMIF($S:$S,$C22,AA:AA) -> 0 | L22: =SUMIF($S:$S,$C22,AB:AB) -> 0 | M22: =SUMIF($S:$S,$C22,AC:AC) -> 0 | N22: =SUMIF($S:$S,$C22,AD:AD) -> 0 | O22: =SUMIF($S:$S,$C22,AE:AE) -> 0 | P22: =SUMIF($S:$S,$C22,AF:AF) -> 0 | R22: 동래상사㈜ | S22: Bud 33cl bottle | T22: 294 | U22: 19 | V22: 30
C23: Blanc 20L & 30L | D23: =SUMIF($S:$S,$C23,T:T) -> 788 | E23: =SUMIF($S:$S,$C23,U:U) -> 47 | F23: =SUMIF($S:$S,$C23,V:V) -> 56 | G23: =SUMIF($S:$S,$C23,W:W) -> 0 | H23: =SUMIF($S:$S,$C23,X:X) -> 0 | I23: =SUMIF($S:$S,$C23,Y:Y) -> 0 | J23: =SUMIF($S:$S,$C23,Z:Z) -> 0 | K23: =SUMIF($S:$S,$C23,AA:AA) -> 0 | L23: =SUMIF($S:$S,$C23,AB:AB) -> 0 | M23: =SUMIF($S:$S,$C23,AC:AC) -> 0 | N23: =SUMIF($S:$S,$C23,AD:AD) -> 0 | O23: =SUMIF($S:$S,$C23,AE:AE) -> 0 | P23: =SUMIF($S:$S,$C23,AF:AF) -> 0 | R23: 동래상사㈜ | S23: Corona 33cl bottle | T23: 240 | U23: 16 | V23: 14
C24: Total | D24: =SUM(D21:D23) -> 788 | E24: =SUM(E21:E23) -> 47 | F24: =SUM(F21:F23) -> 56 | G24: =SUM(G21:G23) -> 0 | H24: =SUM(H21:H23) -> 0 | I24: =SUM(I21:I23) -> 0 | J24: =SUM(J21:J23) -> 0 | K24: =SUM(K21:K23) -> 0 | ... P24: =SUM(P21:P23) -> 0 | R24: 동래상사㈜ | S24: Sulwha 50cl bottle | T24: 85 | U24: 10 | V24: 12
R25: 동래상사㈜ | S25: Harbin 50cl & 64cl bottle | T25: 601 | U25: 39 | V25: 39
R26: 동래상사㈜ | S26: Tsingtao 64cl bottle | T26: 1223 | U26: 75 | V26: 92
R27: 동래상사㈜ | S27: Heineken 8L | T27: 478 | U27: 0 | V27: 24
R28: 동래상사㈜ | S28: Heineken 20L | T28: 425 | U28: 22 | V28: 20
R29: 동래상사㈜ | S29: Stellar 12L & 20L | T29: 540 | U29: 37 | V29: 43
R30: 동래상사㈜ | S30: Asahi 10L & 19L | T30: 430 | U30: 30 | V30: 29
R31: 동래상사㈜ | S31: Paulaner 20L
R32: 동래상사㈜ | S32: Hoegaarden 20L
R33: 동래상사㈜ | S33: Blanc 20L & 30L | T33: 42 | U33: 1 | V33: 0
R35: WS | S35: SKU | T35: Y2025 | U35: Jan'26 | V35: Feb'26 | W35: Mar'26 | X35: Apr'26 | Y35: May'26 | Z35: Jun'26 | AA35: Jul'26 | AB35: Aug'26 | AC35: Sep'26 | AD35: Oct'26 | AE35: Nov'26 | AF35: Dec'26
R36: 삼진㈜ | S36: Heineken 33cl bottle | T36: 1498 | U36: 124 | V36: 114
R37: 삼진㈜ | S37: Stellar 33cl bottle | T37: 345 | U37: 20 | V37: 19
R38: 삼진㈜ | S38: Bud 33cl bottle | T38: 1312 | U38: 80 | V38: 188
R39: 삼진㈜ | S39: Corona 33cl bottle | T39: 2656 | U39: 162 | V39: 183
R40: 삼진㈜ | S40: Sulwha 50cl bottle | T40: 0 | U40: 0 | V40: 0
R41: 삼진㈜ | S41: Harbin 50cl & 64cl bottle | T41: 71 | U41: 5 | V41: 2
R42: 삼진㈜ | S42: Tsingtao 64cl bottle | T42: 211 | U42: 15 | V42: 8
...

Sheet 대전
B2: 1. Bottle market | P2: [단위:QTY] | R2: 3. WS List
C3: SKU | D3: Y2025 | E3: Jan'26 | F3: Feb'26 | G3: Mar'26 | H3: Apr'26 | I3: May'26 | J3: Jun'26 | K3: Jul'26 | L3: Aug'26 | M3: Sep'26 | N3: Oct'26 | O3: Nov'26 | P3: Dec'26 | R3: WS | S3: SKU | T3: Y2025 | U3: Jan'26 | V3: Feb'26 | W3: Mar'26 | X3: Apr'26 | Y3: May'26 | Z3: Jun'26 | AA3: Jul'26 | AB3: Aug'26 | AC3: Sep'26 | AD3: Oct'26 | AE3: Nov'26 | AF3: Dec'26
B4: Western | C4: Heineken 33cl bottle | D4: =SUMIF($S:$S,$C4,T:T) -> 2790 | E4: =SUMIF($S:$S,$C4,U:U) -> 194 | F4: =SUMIF($S:$S,$C4,V:V) -> 149 | G4: =SUMIF($S:$S,$C4,W:W) -> 0 | H4: =SUMIF($S:$S,$C4,X:X) -> 0 | I4: =SUMIF($S:$S,$C4,Y:Y) -> 0 | J4: =SUMIF($S:$S,$C4,Z:Z) -> 0 | K4: =SUMIF($S:$S,$C4,AA:AA) -> 0 | L4: =SUMIF($S:$S,$C4,AB:AB) -> 0 | M4: =SUMIF($S:$S,$C4,AC:AC) -> 0 | N4: =SUMIF($S:$S,$C4,AD:AD) -> 0 | O4: =SUMIF($S:$S,$C4,AE:AE) -> 0 | P4: =SUMIF($S:$S,$C4,AF:AF) -> 0 | R4: 충청주류상사㈜ | S4: Heineken 33cl bottle | T4: 1080 | U4: 78 | V4: 66
C5: Stellar 33cl bottle | D5: =SUMIF($S:$S,$C5,T:T) -> 1097 | E5: =SUMIF($S:$S,$C5,U:U) -> 80 | F5: =SUMIF($S:$S,$C5,V:V) -> 78 | G5: =SUMIF($S:$S,$C5,W:W) -> 0 | H5: =SUMIF($S:$S,$C5,X:X) -> 0 | I5: =SUMIF($S:$S,$C5,Y:Y) -> 0 | J5: =SUMIF($S:$S,$C5,Z:Z) -> 0 | K5: =SUMIF($S:$S,$C5,AA:AA) -> 0 | L5: =SUMIF($S:$S,$C5,AB:AB) -> 0 | M5: =SUMIF($S:$S,$C5,AC:AC) -> 0 | N5: =SUMIF($S:$S,$C5,AD:AD) -> 0 | O5: =SUMIF($S:$S,$C5,AE:AE) -> 0 | P5: =SUMIF($S:$S,$C5,AF:AF) -> 0 | R5: 충청주류상사㈜ | S5: Stellar 33cl bottle | T5: 362 | U5: 27 | V5: 22
C6: Bud 33cl bottle | D6: =SUMIF($S:$S,$C6,T:T) -> 5244 | E6: =SUMIF($S:$S,$C6,U:U) -> 409 | F6: =SUMIF($S:$S,$C6,V:V) -> 458 | G6: =SUMIF($S:$S,$C6,W:W) -> 0 | H6: =SUMIF($S:$S,$C6,X:X) -> 0 | I6: =SUMIF($S:$S,$C6,Y:Y) -> 0 | J6: =SUMIF($S:$S,$C6,Z:Z) -> 0 | K6: =SUMIF($S:$S,$C6,AA:AA) -> 0 | L6: =SUMIF($S:$S,$C6,AB:AB) -> 0 | M6: =SUMIF($S:$S,$C6,AC:AC) -> 0 | N6: =SUMIF($S:$S,$C6,AD:AD) -> 0 | O6: =SUMIF($S:$S,$C6,AE:AE) -> 0 | P6: =SUMIF($S:$S,$C6,AF:AF) -> 0 | R6: 충청주류상사㈜ | S6: Bud 33cl bottle | T6: 2792 | U6: 199 | V6: 196
C7: Corona 33cl bottle | D7: =SUMIF($S:$S,$C7,T:T) -> 810 | E7: =SUMIF($S:$S,$C7,U:U) -> 65 | F7: =SUMIF($S:$S,$C7,V:V) -> 64 | G7: =SUMIF($S:$S,$C7,W:W) -> 0 | H7: =SUMIF($S:$S,$C7,X:X) -> 0 | I7: =SUMIF($S:$S,$C7,Y:Y) -> 0 | J7: =SUMIF($S:$S,$C7,Z:Z) -> 0 | K7: =SUMIF($S:$S,$C7,AA:AA) -> 0 | L7: =SUMIF($S:$S,$C7,AB:AB) -> 0 | M7: =SUMIF($S:$S,$C7,AC:AC) -> 0 | N7: =SUMIF($S:$S,$C7,AD:AD) -> 0 | O7: =SUMIF($S:$S,$C7,AE:AE) -> 0 | P7: =SUMIF($S:$S,$C7,AF:AF) -> 0 | R7: 충청주류상사㈜ | S7: Corona 33cl bottle | T7: 305 | U7: 22 | V7: 23
B8: Total | D8: =SUM(D4:D7) -> 9941 | E8: =SUM(E4:E7) -> 748 | F8: =SUM(F4:F7) -> 749 | G8: =SUM(G4:G7) -> 0 | H8: =SUM(H4:H7) -> 0 | I8: =SUM(I4:I7) -> 0 | J8: =SUM(J4:J7) -> 0 | K8: =SUM(K4:K7) -> 0 | ... P8: =SUM(P4:P7) -> 0 | R8: 충청주류상사㈜ | S8: Sulwha 50cl bottle | T8: 33 | U8: 10 | V8: 5
B9: Chinese | C9: Sulwha 50cl bottle | D9: =SUMIF($S:$S,$C9,T:T) -> 240 | E9: =SUMIF($S:$S,$C9,U:U) -> 43 | F9: =SUMIF($S:$S,$C9,V:V) -> 21 | G9: =SUMIF($S:$S,$C9,W:W) -> 0 | H9: =SUMIF($S:$S,$C9,X:X) -> 0 | I9: =SUMIF($S:$S,$C9,Y:Y) -> 0 | J9: =SUMIF($S:$S,$C9,Z:Z) -> 0 | K9: =SUMIF($S:$S,$C9,AA:AA) -> 0 | L9: =SUMIF($S:$S,$C9,AB:AB) -> 0 | M9: =SUMIF($S:$S,$C9,AC:AC) -> 0 | N9: =SUMIF($S:$S,$C9,AD:AD) -> 0 | O9: =SUMIF($S:$S,$C9,AE:AE) -> 0 | P9: =SUMIF($S:$S,$C9,AF:AF) -> 0 | R9: 충청주류상사㈜ | S9: Harbin 50cl & 64cl bottle | T9: 561 | U9: 35 | V9: 44
C10: Harbin 50cl & 64cl bottle | D10: =SUMIF($S:$S,$C10,T:T) -> 2166 | E10: =SUMIF($S:$S,$C10,U:U) -> 172 | F10: =SUMIF($S:$S,$C10,V:V) -> 157 | G10: =SUMIF($S:$S,$C10,W:W) -> 0 | H10: =SUMIF($S:$S,$C10,X:X) -> 0 | I10: =SUMIF($S:$S,$C10,Y:Y) -> 0 | J10: =SUMIF($S:$S,$C10,Z:Z) -> 0 | K10: =SUMIF($S:$S,$C10,AA:AA) -> 0 | L10: =SUMIF($S:$S,$C10,AB:AB) -> 0 | M10: =SUMIF($S:$S,$C10,AC:AC) -> 0 | N10: =SUMIF($S:$S,$C10,AD:AD) -> 0 | O10: =SUMIF($S:$S,$C10,AE:AE) -> 0 | P10: =SUMIF($S:$S,$C10,AF:AF) -> 0 | R10: 충청주류상사㈜ | S10: Tsingtao 64cl bottle | T10: 1662 | U10: 115 | V10: 123
C11: Tsingtao 64cl bottle | D11: =SUMIF($S:$S,$C11,T:T) -> 6317 | E11: =SUMIF($S:$S,$C11,U:U) -> 519 | F11: =SUMIF($S:$S,$C11,V:V) -> 517 | G11: =SUMIF($S:$S,$C11,W:W) -> 0 | H11: =SUMIF($S:$S,$C11,X:X) -> 0 | I11: =SUMIF($S:$S,$C11,Y:Y) -> 0 | J11: =SUMIF($S:$S,$C11,Z:Z) -> 0 | K11: =SUMIF($S:$S,$C11,AA:AA) -> 0 | L11: =SUMIF($S:$S,$C11,AB:AB) -> 0 | M11: =SUMIF($S:$S,$C11,AC:AC) -> 0 | N11: =SUMIF($S:$S,$C11,AD:AD) -> 0 | O11: =SUMIF($S:$S,$C11,AE:AE) -> 0 | P11: =SUMIF($S:$S,$C11,AF:AF) -> 0 | R11: 충청주류상사㈜ | S11: Heineken 8L | T11: 427 | U11: 29 | V11: 30
B12: Total | D12: =SUM(D9:D11) -> 8723 | E12: =SUM(E9:E11) -> 734 | F12: =SUM(F9:F11) -> 695 | G12: =SUM(G9:G11) -> 0 | H12: =SUM(H9:H11) -> 0 | I12: =SUM(I9:I11) -> 0 | J12: =SUM(J9:J11) -> 0 | K12: =SUM(K9:K11) -> 0 | ... P12: =SUM(P9:P11) -> 0 | R12: 충청주류상사㈜ | S12: Heineken 20L | T12: 128 | U12: 2 | V12: 2
R13: 충청주류상사㈜ | S13: Stellar 12L & 20L | T13: 200 | U13: 14 | V13: 11
B14: 2. Draught market | P14: [단위:QTY] | R14: 충청주류상사㈜ | S14: Asahi 10L & 19L | T14: 692 | U14: 55 | V14: 47
C15: SKU | D15: Y2025 | E15: Jan'26 | F15: Feb'26 | G15: Mar'26 | H15: Apr'26 | I15: May'26 | J15: Jun'26 | K15: Jul'26 | L15: Aug'26 | M15: Sep'26 | N15: Oct'26 | O15: Nov'26 | P15: Dec'26 | R15: 충청주류상사㈜ | S15: Paulaner 20L
B16: Lager | C16: Heineken 8L | D16: =SUMIF($S:$S,$C16,T:T) -> 1004 | E16: =SUMIF($S:$S,$C16,U:U) -> 57 | F16: =SUMIF($S:$S,$C16,V:V) -> 59 | G16: =SUMIF($S:$S,$C16,W:W) -> 0 | H16: =SUMIF($S:$S,$C16,X:X) -> 0 | I16: =SUMIF($S:$S,$C16,Y:Y) -> 0 | J16: =SUMIF($S:$S,$C16,Z:Z) -> 0 | K16: =SUMIF($S:$S,$C16,AA:AA) -> 0 | L16: =SUMIF($S:$S,$C16,AB:AB) -> 0 | M16: =SUMIF($S:$S,$C16,AC:AC) -> 0 | N16: =SUMIF($S:$S,$C16,AD:AD) -> 0 | O16: =SUMIF($S:$S,$C16,AE:AE) -> 0 | P16: =SUMIF($S:$S,$C16,AF:AF) -> 0 | R16: 충청주류상사㈜ | S16: Hoegaarden 20L
C17: Heineken 20L | D17: =SUMIF($S:$S,$C17,T:T) -> 1512 | E17: =SUMIF($S:$S,$C17,U:U) -> 23 | F17: =SUMIF($S:$S,$C17,V:V) -> 45 | G17: =SUMIF($S:$S,$C17,W:W) -> 0 | H17: =SUMIF($S:$S,$C17,X:X) -> 0 | I17: =SUMIF($S:$S,$C17,Y:Y) -> 0 | J17: =SUMIF($S:$S,$C17,Z:Z) -> 0 | K17: =SUMIF($S:$S,$C17,AA:AA) -> 0 | L17: =SUMIF($S:$S,$C17,AB:AB) -> 0 | M17: =SUMIF($S:$S,$C17,AC:AC) -> 0 | N17: =SUMIF($S:$S,$C17,AD:AD) -> 0 | O17: =SUMIF($S:$S,$C17,AE:AE) -> 0 | P17: =SUMIF($S:$S,$C17,AF:AF) -> 0 | R17: 충청주류상사㈜ | S17: Blanc 20L & 30L | T17: 57 | U17: 6 | V17: 4
C18: Stellar 12L & 20L | D18: =SUMIF($S:$S,$C18,T:T) -> 1453 | E18: =SUMIF($S:$S,$C18,U:U) -> 63 | F18: =SUMIF($S:$S,$C18,V:V) -> 62 | G18: =SUMIF($S:$S,$C18,W:W) -> 0 | H18: =SUMIF($S:$S,$C18,X:X) -> 0 | I18: =SUMIF($S:$S,$C18,Y:Y) -> 0 | J18: =SUMIF($S:$S,$C18,Z:Z) -> 0 | K18: =SUMIF($S:$S,$C18,AA:AA) -> 0 | L18: =SUMIF($S:$S,$C18,AB:AB) -> 0 | M18: =SUMIF($S:$S,$C18,AC:AC) -> 0 | N18: =SUMIF($S:$S,$C18,AD:AD) -> 0 | O18: =SUMIF($S:$S,$C18,AE:AE) -> 0 | P18: =SUMIF($S:$S,$C18,AF:AF) -> 0
C19: Asahi 10L & 19L | D19: =SUMIF($S:$S,$C19,T:T) -> 2536 | E19: =SUMIF($S:$S,$C19,U:U) -> 168 | F19: =SUMIF($S:$S,$C19,V:V) -> 164 | G19: =SUMIF($S:$S,$C19,W:W) -> 0 | H19: =SUMIF($S:$S,$C19,X:X) -> 0 | I19: =SUMIF($S:$S,$C19,Y:Y) -> 0 | J19: =SUMIF($S:$S,$C19,Z:Z) -> 0 | K19: =SUMIF($S:$S,$C19,AA:AA) -> 0 | L19: =SUMIF($S:$S,$C19,AB:AB) -> 0 | M19: =SUMIF($S:$S,$C19,AC:AC) -> 0 | N19: =SUMIF($S:$S,$C19,AD:AD) -> 0 | O19: =SUMIF($S:$S,$C19,AE:AE) -> 0 | P19: =SUMIF($S:$S,$C19,AF:AF) -> 0 | R19: WS | S19: SKU | T19: Y2025 | U19: Jan'26 | V19: Feb'26 | W19: Mar'26 | X19: Apr'26 | Y19: May'26 | Z19: Jun'26 | AA19: Jul'26 | AB19: Aug'26 | AC19: Sep'26 | AD19: Oct'26 | AE19: Nov'26 | AF19: Dec'26
C20: Total | D20: =SUM(D16:D19) -> 6505 | E20: =SUM(E16:E19) -> 311 | F20: =SUM(F16:F19) -> 330 | G20: =SUM(G16:G19) -> 0 | H20: =SUM(H16:H19) -> 0 | I20: =SUM(I16:I19) -> 0 | J20: =SUM(J16:J19) -> 0 | K20: =SUM(K16:K19) -> 0 | ... P20: =SUM(P16:P19) -> 0 | R20: 청주주류상사㈜ | S20: Heineken 33cl bottle | T20: 223 | U20: 12 | V20: 25
B21: Wheat | C21: Paulaner 20L | D21: =SUMIF($S:$S,$C21,T:T) -> 0 | E21: =SUMIF($S:$S,$C21,U:U) -> 0 | F21: =SUMIF($S:$S,$C21,V:V) -> 0 | G21: =SUMIF($S:$S,$C21,W:W) -> 0 | H21: =SUMIF($S:$S,$C21,X:X) -> 0 | I21: =SUMIF($S:$S,$C21,Y:Y) -> 0 | J21: =SUMIF($S:$S,$C21,Z:Z) -> 0 | K21: =SUMIF($S:$S,$C21,AA:AA) -> 0 | L21: =SUMIF($S:$S,$C21,AB:AB) -> 0 | M21: =SUMIF($S:$S,$C21,AC:AC) -> 0 | N21: =SUMIF($S:$S,$C21,AD:AD) -> 0 | O21: =SUMIF($S:$S,$C21,AE:AE) -> 0 | P21: =SUMIF($S:$S,$C21,AF:AF) -> 0 | R21: 청주주류상사㈜ | S21: Stellar 33cl bottle | T21: 43 | U21: 5 | V21: 8
C22: Hoegaarden 20L | D22: =SUMIF($S:$S,$C22,T:T) -> 0 | E22: =SUMIF($S:$S,$C22,U:U) -> 0 | F22: =SUMIF($S:$S,$C22,V:V) -> 0 | G22: =SUMIF($S:$S,$C22,W:W) -> 0 | H22: =SUMIF($S:$S,$C22,X:X) -> 0 | I22: =SUMIF($S:$S,$C22,Y:Y) -> 0 | J22: =SUMIF($S:$S,$C22,Z:Z) -> 0 | K22: =SUMIF($S:$S,$C22,AA:AA) -> 0 | L22: =SUMIF($S:$S,$C22,AB:AB) -> 0 | M22: =SUMIF($S:$S,$C22,AC:AC) -> 0 | N22: =SUMIF($S:$S,$C22,AD:AD) -> 0 | O22: =SUMIF($S:$S,$C22,AE:AE) -> 0 | P22: =SUMIF($S:$S,$C22,AF:AF) -> 0 | R22: 청주주류상사㈜ | S22: Bud 33cl bottle | T22: 482 | U22: 34 | V22: 40
C23: Blanc 20L & 30L | D23: =SUMIF($S:$S,$C23,T:T) -> 124 | E23: =SUMIF($S:$S,$C23,U:U) -> 10 | F23: =SUMIF($S:$S,$C23,V:V) -> 7 | G23: =SUMIF($S:$S,$C23,W:W) -> 0 | H23: =SUMIF($S:$S,$C23,X:X) -> 0 | I23: =SUMIF($S:$S,$C23,Y:Y) -> 0 | J23: =SUMIF($S:$S,$C23,Z:Z) -> 0 | K23: =SUMIF($S:$S,$C23,AA:AA) -> 0 | L23: =SUMIF($S:$S,$C23,AB:AB) -> 0 | M23: =SUMIF($S:$S,$C23,AC:AC) -> 0 | N23: =SUMIF($S:$S,$C23,AD:AD) -> 0 | O23: =SUMIF($S:$S,$C23,AE:AE) -> 0 | P23: =SUMIF($S:$S,$C23,AF:AF) -> 0 | R23: 청주주류상사㈜ | S23: Corona 33cl bottle | T23: 48 | U23: 5 | V23: 4
C24: Total | D24: =SUM(D21:D23) -> 124 | E24: =SUM(E21:E23) -> 10 | F24: =SUM(F21:F23) -> 7 | G24: =SUM(G21:G23) -> 0 | H24: =SUM(H21:H23) -> 0 | I24: =SUM(I21:I23) -> 0 | J24: =SUM(J21:J23) -> 0 | K24: =SUM(K21:K23) -> 0 | ... P24: =SUM(P21:P23) -> 0 | R24: 청주주류상사㈜ | S24: Sulwha 50cl bottle | T24: 30 | U24: 2 | V24: 2
R25: 청주주류상사㈜ | S25: Harbin 50cl & 64cl bottle | T25: 493 | U25: 38 | V25: 30
R26: 청주주류상사㈜ | S26: Tsingtao 64cl bottle | T26: 1043 | U26: 76 | V26: 3
R27: 청주주류상사㈜ | S27: Heineken 8L | T27: 12 | U27: 0 | V27: 0
R28: 청주주류상사㈜ | S28: Heineken 20L | T28: 18 | U28: 3 | V28: 1
R29: 청주주류상사㈜ | S29: Stellar 12L & 20L | T29: 68 | U29: 3 | V29: 10
R30: 청주주류상사㈜ | S30: Asahi 10L & 19L | T30: 114 | U30: 5 | V30: 11
R31: 청주주류상사㈜ | S31: Paulaner 20L
R32: 청주주류상사㈜ | S32: Hoegaarden 20L
R33: 청주주류상사㈜ | S33: Blanc 20L & 30L | T33: 17 | U33: 2 | V33: 1
R35: WS | S35: SKU | T35: Y2025 | U35: Jan'26 | V35: Feb'26 | W35: Mar'26 | X35: Apr'26 | Y35: May'26 | Z35: Jun'26 | AA35: Jul'26 | AB35: Aug'26 | AC35: Sep'26 | AD35: Oct'26 | AE35: Nov'26 | AF35: Dec'26
R36: 보은주류합동㈜ | S36: Heineken 33cl bottle | T36: 236 | U36: 17 | V36: 13
R37: 보은주류합동㈜ | S37: Stellar 33cl bottle | T37: 88 | U37: 13 | V37: 1
R38: 보은주류합동㈜ | S38: Bud 33cl bottle | T38: 609 | U38: 67 | V38: 52
R39: 보은주류합동㈜ | S39: Corona 33cl bottle | T39: 108 | U39: 13 | V39: 12
R40: 보은주류합동㈜ | S40: Sulwha 50cl bottle | T40: 0 | U40: 0 | V40: 0
R41: 보은주류합동㈜ | S41: Harbin 50cl & 64cl bottle | T41: 311 | U41: 31 | V41: 28
R42: 보은주류합동㈜ | S42: Tsingtao 64cl bottle | T42: 340 | U42: 30 | V42: 29
...

Sheet 대구
B2: 1. Bottle market | P2: [단위:QTY] | R2: 3. WS List
C3: SKU | D3: Y2025 | E3: Jan'26 | F3: Feb'26 | G3: Mar'26 | H3: Apr'26 | I3: May'26 | J3: Jun'26 | K3: Jul'26 | L3: Aug'26 | M3: Sep'26 | N3: Oct'26 | O3: Nov'26 | P3: Dec'26 | R3: WS | S3: SKU | T3: Y2025 | U3: Jan'26 | V3: Feb'26 | W3: Mar'26 | X3: Apr'26 | Y3: May'26 | Z3: Jun'26 | AA3: Jul'26 | AB3: Aug'26 | AC3: Sep'26 | AD3: Oct'26 | AE3: Nov'26 | AF3: Dec'26
B4: Western | C4: Heineken 33cl bottle | D4: =SUMIF($S:$S,$C4,T:T) -> 3053 | E4: =SUMIF($S:$S,$C4,U:U) -> 231 | F4: =SUMIF($S:$S,$C4,V:V) -> 151 | G4: =SUMIF($S:$S,$C4,W:W) -> 0 | H4: =SUMIF($S:$S,$C4,X:X) -> 0 | I4: =SUMIF($S:$S,$C4,Y:Y) -> 0 | J4: =SUMIF($S:$S,$C4,Z:Z) -> 0 | K4: =SUMIF($S:$S,$C4,AA:AA) -> 0 | L4: =SUMIF($S:$S,$C4,AB:AB) -> 0 | M4: =SUMIF($S:$S,$C4,AC:AC) -> 0 | N4: =SUMIF($S:$S,$C4,AD:AD) -> 0 | O4: =SUMIF($S:$S,$C4,AE:AE) -> 0 | P4: =SUMIF($S:$S,$C4,AF:AF) -> 0 | R4: 세계주류상사(주)대구 | S4: Heineken 33cl bottle | T4: 360 | U4: 29
C5: Stellar 33cl bottle | D5: =SUMIF($S:$S,$C5,T:T) -> 1082 | E5: =SUMIF($S:$S,$C5,U:U) -> 74 | F5: =SUMIF($S:$S,$C5,V:V) -> 40 | G5: =SUMIF($S:$S,$C5,W:W) -> 0 | H5: =SUMIF($S:$S,$C5,X:X) -> 0 | I5: =SUMIF($S:$S,$C5,Y:Y) -> 0 | J5: =SUMIF($S:$S,$C5,Z:Z) -> 0 | K5: =SUMIF($S:$S,$C5,AA:AA) -> 0 | L5: =SUMIF($S:$S,$C5,AB:AB) -> 0 | M5: =SUMIF($S:$S,$C5,AC:AC) -> 0 | N5: =SUMIF($S:$S,$C5,AD:AD) -> 0 | O5: =SUMIF($S:$S,$C5,AE:AE) -> 0 | P5: =SUMIF($S:$S,$C5,AF:AF) -> 0 | R5: 세계주류상사(주)대구 | S5: Stellar 33cl bottle | T5: 90 | U5: 3
C6: Bud 33cl bottle | D6: =SUMIF($S:$S,$C6,T:T) -> 4169 | E6: =SUMIF($S:$S,$C6,U:U) -> 330 | F6: =SUMIF($S:$S,$C6,V:V) -> 336 | G6: =SUMIF($S:$S,$C6,W:W) -> 0 | H6: =SUMIF($S:$S,$C6,X:X) -> 0 | I6: =SUMIF($S:$S,$C6,Y:Y) -> 0 | J6: =SUMIF($S:$S,$C6,Z:Z) -> 0 | K6: =SUMIF($S:$S,$C6,AA:AA) -> 0 | L6: =SUMIF($S:$S,$C6,AB:AB) -> 0 | M6: =SUMIF($S:$S,$C6,AC:AC) -> 0 | N6: =SUMIF($S:$S,$C6,AD:AD) -> 0 | O6: =SUMIF($S:$S,$C6,AE:AE) -> 0 | P6: =SUMIF($S:$S,$C6,AF:AF) -> 0 | R6: 세계주류상사(주)대구 | S6: Bud 33cl bottle | T6: 60 | U6: 0
C7: Corona 33cl bottle | D7: =SUMIF($S:$S,$C7,T:T) -> 3052 | E7: =SUMIF($S:$S,$C7,U:U) -> 176 | F7: =SUMIF($S:$S,$C7,V:V) -> 155 | G7: =SUMIF($S:$S,$C7,W:W) -> 0 | H7: =SUMIF($S:$S,$C7,X:X) -> 0 | I7: =SUMIF($S:$S,$C7,Y:Y) -> 0 | J7: =SUMIF($S:$S,$C7,Z:Z) -> 0 | K7: =SUMIF($S:$S,$C7,AA:AA) -> 0 | L7: =SUMIF($S:$S,$C7,AB:AB) -> 0 | M7: =SUMIF($S:$S,$C7,AC:AC) -> 0 | N7: =SUMIF($S:$S,$C7,AD:AD) -> 0 | O7: =SUMIF($S:$S,$C7,AE:AE) -> 0 | P7: =SUMIF($S:$S,$C7,AF:AF) -> 0 | R7: 세계주류상사(주)대구 | S7: Corona 33cl bottle | T7: 300 | U7: 15
B8: Total | D8: =SUM(D4:D7) -> 11356 | E8: =SUM(E4:E7) -> 811 | F8: =SUM(F4:F7) -> 682 | G8: =SUM(G4:G7) -> 0 | H8: =SUM(H4:H7) -> 0 | I8: =SUM(I4:I7) -> 0 | J8: =SUM(J4:J7) -> 0 | K8: =SUM(K4:K7) -> 0 | ... P8: =SUM(P4:P7) -> 0 | R8: 세계주류상사(주)대구 | S8: Sulwha 50cl bottle | T8: 0 | U8: 0
B9: Chinese | C9: Sulwha 50cl bottle | D9: =SUMIF($S:$S,$C9,T:T) -> 721 | E9: =SUMIF($S:$S,$C9,U:U) -> 40 | F9: =SUMIF($S:$S,$C9,V:V) -> 38 | G9: =SUMIF($S:$S,$C9,W:W) -> 0 | H9: =SUMIF($S:$S,$C9,X:X) -> 0 | I9: =SUMIF($S:$S,$C9,Y:Y) -> 0 | J9: =SUMIF($S:$S,$C9,Z:Z) -> 0 | K9: =SUMIF($S:$S,$C9,AA:AA) -> 0 | L9: =SUMIF($S:$S,$C9,AB:AB) -> 0 | M9: =SUMIF($S:$S,$C9,AC:AC) -> 0 | N9: =SUMIF($S:$S,$C9,AD:AD) -> 0 | O9: =SUMIF($S:$S,$C9,AE:AE) -> 0 | P9: =SUMIF($S:$S,$C9,AF:AF) -> 0 | R9: 세계주류상사(주)대구 | S9: Harbin 50cl & 64cl bottle | T9: 40 | U9: 5
C10: Harbin 50cl & 64cl bottle | D10: =SUMIF($S:$S,$C10,T:T) -> 1246 | E10: =SUMIF($S:$S,$C10,U:U) -> 75 | F10: =SUMIF($S:$S,$C10,V:V) -> 104 | G10: =SUMIF($S:$S,$C10,W:W) -> 0 | H10: =SUMIF($S:$S,$C10,X:X) -> 0 | I10: =SUMIF($S:$S,$C10,Y:Y) -> 0 | J10: =SUMIF($S:$S,$C10,Z:Z) -> 0 | K10: =SUMIF($S:$S,$C10,AA:AA) -> 0 | L10: =SUMIF($S:$S,$C10,AB:AB) -> 0 | M10: =SUMIF($S:$S,$C10,AC:AC) -> 0 | N10: =SUMIF($S:$S,$C10,AD:AD) -> 0 | O10: =SUMIF($S:$S,$C10,AE:AE) -> 0 | P10: =SUMIF($S:$S,$C10,AF:AF) -> 0 | R10: 세계주류상사(주)대구 | S10: Tsingtao 64cl bottle | T10: 170 | U10: 15
C11: Tsingtao 64cl bottle | D11: =SUMIF($S:$S,$C11,T:T) -> 4624 | E11: =SUMIF($S:$S,$C11,U:U) -> 373 | F11: =SUMIF($S:$S,$C11,V:V) -> 383 | G11: =SUMIF($S:$S,$C11,W:W) -> 0 | H11: =SUMIF($S:$S,$C11,X:X) -> 0 | I11: =SUMIF($S:$S,$C11,Y:Y) -> 0 | J11: =SUMIF($S:$S,$C11,Z:Z) -> 0 | K11: =SUMIF($S:$S,$C11,AA:AA) -> 0 | L11: =SUMIF($S:$S,$C11,AB:AB) -> 0 | M11: =SUMIF($S:$S,$C11,AC:AC) -> 0 | N11: =SUMIF($S:$S,$C11,AD:AD) -> 0 | O11: =SUMIF($S:$S,$C11,AE:AE) -> 0 | P11: =SUMIF($S:$S,$C11,AF:AF) -> 0 | R11: 세계주류상사(주)대구 | S11: Heineken 8L | T11: 220 | U11: 13
B12: Total | D12: =SUM(D9:D11) -> 6591 | E12: =SUM(E9:E11) -> 488 | F12: =SUM(F9:F11) -> 525 | G12: =SUM(G9:G11) -> 0 | H12: =SUM(H9:H11) -> 0 | I12: =SUM(I9:I11) -> 0 | J12: =SUM(J9:J11) -> 0 | K12: =SUM(K9:K11) -> 0 | ... P12: =SUM(P9:P11) -> 0 | R12: 세계주류상사(주)대구 | S12: Heineken 20L | T12: 3228 | U12: 35
R13: 세계주류상사(주)대구 | S13: Stellar 12L & 20L | T13: 150 | U13: 0
B14: 2. Draught market | P14: [단위:QTY] | R14: 세계주류상사(주)대구 | S14: Asahi 10L & 19L | T14: 1813 | U14: 144
C15: SKU | D15: Y2025 | E15: Jan'26 | F15: Feb'26 | G15: Mar'26 | H15: Apr'26 | I15: May'26 | J15: Jun'26 | K15: Jul'26 | L15: Aug'26 | M15: Sep'26 | N15: Oct'26 | O15: Nov'26 | P15: Dec'26 | R15: 세계주류상사(주)대구 | S15: Paulaner 20L
B16: Lager | C16: Heineken 8L | D16: =SUMIF($S:$S,$C16,T:T) -> 3887 | E16: =SUMIF($S:$S,$C16,U:U) -> 270 | F16: =SUMIF($S:$S,$C16,V:V) -> 185 | G16: =SUMIF($S:$S,$C16,W:W) -> 0 | H16: =SUMIF($S:$S,$C16,X:X) -> 0 | I16: =SUMIF($S:$S,$C16,Y:Y) -> 0 | J16: =SUMIF($S:$S,$C16,Z:Z) -> 0 | K16: =SUMIF($S:$S,$C16,AA:AA) -> 0 | L16: =SUMIF($S:$S,$C16,AB:AB) -> 0 | M16: =SUMIF($S:$S,$C16,AC:AC) -> 0 | N16: =SUMIF($S:$S,$C16,AD:AD) -> 0 | O16: =SUMIF($S:$S,$C16,AE:AE) -> 0 | P16: =SUMIF($S:$S,$C16,AF:AF) -> 0 | R16: 세계주류상사(주)대구 | S16: Hoegaarden 20L
C17: Heineken 20L | D17: =SUMIF($S:$S,$C17,T:T) -> 7348 | E17: =SUMIF($S:$S,$C17,U:U) -> 172 | F17: =SUMIF($S:$S,$C17,V:V) -> 284 | G17: =SUMIF($S:$S,$C17,W:W) -> 0 | H17: =SUMIF($S:$S,$C17,X:X) -> 0 | I17: =SUMIF($S:$S,$C17,Y:Y) -> 0 | J17: =SUMIF($S:$S,$C17,Z:Z) -> 0 | K17: =SUMIF($S:$S,$C17,AA:AA) -> 0 | L17: =SUMIF($S:$S,$C17,AB:AB) -> 0 | M17: =SUMIF($S:$S,$C17,AC:AC) -> 0 | N17: =SUMIF($S:$S,$C17,AD:AD) -> 0 | O17: =SUMIF($S:$S,$C17,AE:AE) -> 0 | P17: =SUMIF($S:$S,$C17,AF:AF) -> 0 | R17: 세계주류상사(주)대구 | S17: Blanc 20L & 30L | T17: 400 | U17: 15
C18: Stellar 12L & 20L | D18: =SUMIF($S:$S,$C18,T:T) -> 5459 | E18: =SUMIF($S:$S,$C18,U:U) -> 283 | F18: =SUMIF($S:$S,$C18,V:V) -> 286 | G18: =SUMIF($S:$S,$C18,W:W) -> 0 | H18: =SUMIF($S:$S,$C18,X:X) -> 0 | I18: =SUMIF($S:$S,$C18,Y:Y) -> 0 | J18: =SUMIF($S:$S,$C18,Z:Z) -> 0 | K18: =SUMIF($S:$S,$C18,AA:AA) -> 0 | L18: =SUMIF($S:$S,$C18,AB:AB) -> 0 | M18: =SUMIF($S:$S,$C18,AC:AC) -> 0 | N18: =SUMIF($S:$S,$C18,AD:AD) -> 0 | O18: =SUMIF($S:$S,$C18,AE:AE) -> 0 | P18: =SUMIF($S:$S,$C18,AF:AF) -> 0
C19: Asahi 10L & 19L | D19: =SUMIF($S:$S,$C19,T:T) -> 11246 | E19: =SUMIF($S:$S,$C19,U:U) -> 853 | F19: =SUMIF($S:$S,$C19,V:V) -> 646 | G19: =SUMIF($S:$S,$C19,W:W) -> 0 | H19: =SUMIF($S:$S,$C19,X:X) -> 0 | I19: =SUMIF($S:$S,$C19,Y:Y) -> 0 | J19: =SUMIF($S:$S,$C19,Z:Z) -> 0 | K19: =SUMIF($S:$S,$C19,AA:AA) -> 0 | L19: =SUMIF($S:$S,$C19,AB:AB) -> 0 | M19: =SUMIF($S:$S,$C19,AC:AC) -> 0 | N19: =SUMIF($S:$S,$C19,AD:AD) -> 0 | O19: =SUMIF($S:$S,$C19,AE:AE) -> 0 | P19: =SUMIF($S:$S,$C19,AF:AF) -> 0 | R19: WS | S19: SKU | T19: Y2025 | U19: Jan'26 | V19: Feb'26 | W19: Mar'26 | X19: Apr'26 | Y19: May'26 | Z19: Jun'26 | AA19: Jul'26 | AB19: Aug'26 | AC19: Sep'26 | AD19: Oct'26 | AE19: Nov'26 | AF19: Dec'26
C20: Total | D20: =SUM(D16:D19) -> 27940 | E20: =SUM(E16:E19) -> 1578 | F20: =SUM(F16:F19) -> 1401 | G20: =SUM(G16:G19) -> 0 | H20: =SUM(H16:H19) -> 0 | I20: =SUM(I16:I19) -> 0 | J20: =SUM(J16:J19) -> 0 | K20: =SUM(K16:K19) -> 0 | ... P20: =SUM(P16:P19) -> 0 | R20: 에스엠종합주류 | S20: Heineken 33cl bottle | T20: 328 | U20: 19 | V20: 17
B21: Wheat | C21: Paulaner 20L | D21: =SUMIF($S:$S,$C21,T:T) -> 0 | E21: =SUMIF($S:$S,$C21,U:U) -> 0 | F21: =SUMIF($S:$S,$C21,V:V) -> 0 | G21: =SUMIF($S:$S,$C21,W:W) -> 0 | H21: =SUMIF($S:$S,$C21,X:X) -> 0 | I21: =SUMIF($S:$S,$C21,Y:Y) -> 0 | J21: =SUMIF($S:$S,$C21,Z:Z) -> 0 | K21: =SUMIF($S:$S,$C21,AA:AA) -> 0 | L21: =SUMIF($S:$S,$C21,AB:AB) -> 0 | M21: =SUMIF($S:$S,$C21,AC:AC) -> 0 | N21: =SUMIF($S:$S,$C21,AD:AD) -> 0 | O21: =SUMIF($S:$S,$C21,AE:AE) -> 0 | P21: =SUMIF($S:$S,$C21,AF:AF) -> 0 | R21: 에스엠종합주류 | S21: Stellar 33cl bottle | T21: 58 | U21: 5 | V21: 5
C22: Hoegaarden 20L | D22: =SUMIF($S:$S,$C22,T:T) -> 0 | E22: =SUMIF($S:$S,$C22,U:U) -> 0 | F22: =SUMIF($S:$S,$C22,V:V) -> 0 | G22: =SUMIF($S:$S,$C22,W:W) -> 0 | H22: =SUMIF($S:$S,$C22,X:X) -> 0 | I22: =SUMIF($S:$S,$C22,Y:Y) -> 0 | J22: =SUMIF($S:$S,$C22,Z:Z) -> 0 | K22: =SUMIF($S:$S,$C22,AA:AA) -> 0 | L22: =SUMIF($S:$S,$C22,AB:AB) -> 0 | M22: =SUMIF($S:$S,$C22,AC:AC) -> 0 | N22: =SUMIF($S:$S,$C22,AD:AD) -> 0 | O22: =SUMIF($S:$S,$C22,AE:AE) -> 0 | P22: =SUMIF($S:$S,$C22,AF:AF) -> 0 | R22: 에스엠종합주류 | S22: Bud 33cl bottle | T22: 643 | U22: 68 | V22: 70
C23: Blanc 20L & 30L | D23: =SUMIF($S:$S,$C23,T:T) -> 2424 | E23: =SUMIF($S:$S,$C23,U:U) -> 156 | F23: =SUMIF($S:$S,$C23,V:V) -> 41 | G23: =SUMIF($S:$S,$C23,W:W) -> 0 | H23: =SUMIF($S:$S,$C23,X:X) -> 0 | I23: =SUMIF($S:$S,$C23,Y:Y) -> 0 | J23: =SUMIF($S:$S,$C23,Z:Z) -> 0 | K23: =SUMIF($S:$S,$C23,AA:AA) -> 0 | L23: =SUMIF($S:$S,$C23,AB:AB) -> 0 | M23: =SUMIF($S:$S,$C23,AC:AC) -> 0 | N23: =SUMIF($S:$S,$C23,AD:AD) -> 0 | O23: =SUMIF($S:$S,$C23,AE:AE) -> 0 | P23: =SUMIF($S:$S,$C23,AF:AF) -> 0 | R23: 에스엠종합주류 | S23: Corona 33cl bottle | T23: 431 | U23: 25 | V23: 43
C24: Total | D24: =SUM(D21:D23) -> 2424 | E24: =SUM(E21:E23) -> 156 | F24: =SUM(F21:F23) -> 41 | G24: =SUM(G21:G23) -> 0 | H24: =SUM(H21:H23) -> 0 | I24: =SUM(I21:I23) -> 0 | J24: =SUM(J21:J23) -> 0 | K24: =SUM(K21:K23) -> 0 | ... P24: =SUM(P21:P23) -> 0 | R24: 에스엠종합주류 | S24: Sulwha 50cl bottle | T24: 8 | U24: 1 | V24: 2
R25: 에스엠종합주류 | S25: Harbin 50cl & 64cl bottle | T25: 18 | U25: 9 | V25: 3
R26: 에스엠종합주류 | S26: Tsingtao 64cl bottle | T26: 357 | U26: 28 | V26: 31
R27: 에스엠종합주류 | S27: Heineken 8L | T27: 336 | U27: 27 | V27: 19
R28: 에스엠종합주류 | S28: Heineken 20L | T28: 640 | U28: 33 | V28: 23
R29: 에스엠종합주류 | S29: Stellar 12L & 20L | T29: 335 | U29: 35 | V29: 50
R30: 에스엠종합주류 | S30: Asahi 10L & 19L | T30: 1751 | U30: 154 | V30: 150
R31: 에스엠종합주류 | S31: Paulaner 20L
R32: 에스엠종합주류 | S32: Hoegaarden 20L
R33: 에스엠종합주류 | S33: Blanc 20L & 30L | T33: 160 | U33: 20 | V33: 20
R35: WS | S35: SKU | T35: Y2025 | U35: Jan'26 | V35: Feb'26 | W35: Mar'26 | X35: Apr'26 | Y35: May'26 | Z35: Jun'26 | AA35: Jul'26 | AB35: Aug'26 | AC35: Sep'26 | AD35: Oct'26 | AE35: Nov'26 | AF35: Dec'26
R36: 대성주류상사(주) | S36: Heineken 33cl bottle | T36: 497 | U36: 27 | V36: 61
R37: 대성주류상사(주) | S37: Stellar 33cl bottle | T37: 61 | U37: 3 | V37: 3
R38: 대성주류상사(주) | S38: Bud 33cl bottle | T38: 0 | U38: 0 | V38: 0
R39: 대성주류상사(주) | S39: Corona 33cl bottle | T39: 416 | U39: 29 | V39: 28
R40: 대성주류상사(주) | S40: Sulwha 50cl bottle | T40: 151 | U40: 10 | V40: 0
R41: 대성주류상사(주) | S41: Harbin 50cl & 64cl bottle | T41: 1 | U41: 0 | V41: 0
R42: 대성주류상사(주) | S42: Tsingtao 64cl bottle | T42: 187 | U42: 6 | V42: 34
...

Sheet 광주
B2: 1. Bottle market | P2: [단위:QTY] | R2: 3. WS List
C3: SKU | D3: Y2025 | E3: Jan'26 | F3: Feb'26 | G3: Mar'26 | H3: Apr'26 | I3: May'26 | J3: Jun'26 | K3: Jul'26 | L3: Aug'26 | M3: Sep'26 | N3: Oct'26 | O3: Nov'26 | P3: Dec'26 | R3: WS | S3: SKU | T3: Y2025 | U3: Jan'26 | V3: Feb'26 | W3: Mar'26 | X3: Apr'26 | Y3: May'26 | Z3: Jun'26 | AA3: Jul'26 | AB3: Aug'26 | AC3: Sep'26 | AD3: Oct'26 | AE3: Nov'26 | AF3: Dec'26
B4: Western | C4: Heineken 33cl bottle | D4: =SUMIF($S:$S,$C4,T:T) -> 2393 | E4: =SUMIF($S:$S,$C4,U:U) -> 155 | F4: =SUMIF($S:$S,$C4,V:V) -> 167 | G4: =SUMIF($S:$S,$C4,W:W) -> 0 | H4: =SUMIF($S:$S,$C4,X:X) -> 0 | I4: =SUMIF($S:$S,$C4,Y:Y) -> 0 | J4: =SUMIF($S:$S,$C4,Z:Z) -> 0 | K4: =SUMIF($S:$S,$C4,AA:AA) -> 0 | L4: =SUMIF($S:$S,$C4,AB:AB) -> 0 | M4: =SUMIF($S:$S,$C4,AC:AC) -> 0 | N4: =SUMIF($S:$S,$C4,AD:AD) -> 0 | O4: =SUMIF($S:$S,$C4,AE:AE) -> 0 | P4: =SUMIF($S:$S,$C4,AF:AF) -> 0 | R4: 디오니 | S4: Heineken 33cl bottle | T4: 763 | U4: 41 | V4: 62
C5: Stellar 33cl bottle | D5: =SUMIF($S:$S,$C5,T:T) -> 890 | E5: =SUMIF($S:$S,$C5,U:U) -> 70 | F5: =SUMIF($S:$S,$C5,V:V) -> 87 | G5: =SUMIF($S:$S,$C5,W:W) -> 0 | H5: =SUMIF($S:$S,$C5,X:X) -> 0 | I5: =SUMIF($S:$S,$C5,Y:Y) -> 0 | J5: =SUMIF($S:$S,$C5,Z:Z) -> 0 | K5: =SUMIF($S:$S,$C5,AA:AA) -> 0 | L5: =SUMIF($S:$S,$C5,AB:AB) -> 0 | M5: =SUMIF($S:$S,$C5,AC:AC) -> 0 | N5: =SUMIF($S:$S,$C5,AD:AD) -> 0 | O5: =SUMIF($S:$S,$C5,AE:AE) -> 0 | P5: =SUMIF($S:$S,$C5,AF:AF) -> 0 | R5: 디오니 | S5: Stellar 33cl bottle | T5: 500 | U5: 40 | V5: 50
C6: Bud 33cl bottle | D6: =SUMIF($S:$S,$C6,T:T) -> 5100 | E6: =SUMIF($S:$S,$C6,U:U) -> 398 | F6: =SUMIF($S:$S,$C6,V:V) -> 237 | G6: =SUMIF($S:$S,$C6,W:W) -> 0 | H6: =SUMIF($S:$S,$C6,X:X) -> 0 | I6: =SUMIF($S:$S,$C6,Y:Y) -> 0 | J6: =SUMIF($S:$S,$C6,Z:Z) -> 0 | K6: =SUMIF($S:$S,$C6,AA:AA) -> 0 | L6: =SUMIF($S:$S,$C6,AB:AB) -> 0 | M6: =SUMIF($S:$S,$C6,AC:AC) -> 0 | N6: =SUMIF($S:$S,$C6,AD:AD) -> 0 | O6: =SUMIF($S:$S,$C6,AE:AE) -> 0 | P6: =SUMIF($S:$S,$C6,AF:AF) -> 0 | R6: 디오니 | S6: Bud 33cl bottle | T6: 1200 | U6: 88 | V6: 90
C7: Corona 33cl bottle | D7: =SUMIF($S:$S,$C7,T:T) -> 680 | E7: =SUMIF($S:$S,$C7,U:U) -> 54 | F7: =SUMIF($S:$S,$C7,V:V) -> 51 | G7: =SUMIF($S:$S,$C7,W:W) -> 0 | H7: =SUMIF($S:$S,$C7,X:X) -> 0 | I7: =SUMIF($S:$S,$C7,Y:Y) -> 0 | J7: =SUMIF($S:$S,$C7,Z:Z) -> 0 | K7: =SUMIF($S:$S,$C7,AA:AA) -> 0 | L7: =SUMIF($S:$S,$C7,AB:AB) -> 0 | M7: =SUMIF($S:$S,$C7,AC:AC) -> 0 | N7: =SUMIF($S:$S,$C7,AD:AD) -> 0 | O7: =SUMIF($S:$S,$C7,AE:AE) -> 0 | P7: =SUMIF($S:$S,$C7,AF:AF) -> 0 | R7: 디오니 | S7: Corona 33cl bottle | T7: 250 | U7: 20 | V7: 15
B8: Total | D8: =SUM(D4:D7) -> 9063 | E8: =SUM(E4:E7) -> 677 | F8: =SUM(F4:F7) -> 542 | G8: =SUM(G4:G7) -> 0 | H8: =SUM(H4:H7) -> 0 | I8: =SUM(I4:I7) -> 0 | J8: =SUM(J4:J7) -> 0 | K8: =SUM(K4:K7) -> 0 | ... P8: =SUM(P4:P7) -> 0 | R8: 디오니 | S8: Sulwha 50cl bottle | T8: 26 | U8: =2*0.76 -> 1.52 | V8: 1
B9: Chinese | C9: Sulwha 50cl bottle | D9: =SUMIF($S:$S,$C9,T:T) -> 1562 | E9: =SUMIF($S:$S,$C9,U:U) -> 114.2 | F9: =SUMIF($S:$S,$C9,V:V) -> 140 | G9: =SUMIF($S:$S,$C9,W:W) -> 0 | H9: =SUMIF($S:$S,$C9,X:X) -> 0 | I9: =SUMIF($S:$S,$C9,Y:Y) -> 0 | J9: =SUMIF($S:$S,$C9,Z:Z) -> 0 | K9: =SUMIF($S:$S,$C9,AA:AA) -> 0 | L9: =SUMIF($S:$S,$C9,AB:AB) -> 0 | M9: =SUMIF($S:$S,$C9,AC:AC) -> 0 | N9: =SUMIF($S:$S,$C9,AD:AD) -> 0 | O9: =SUMIF($S:$S,$C9,AE:AE) -> 0 | P9: =SUMIF($S:$S,$C9,AF:AF) -> 0 | R9: 디오니 | S9: Harbin 50cl & 64cl bottle | T9: 160 | U9: 13 | V9: 15
